Not Found: /favicon.ico
Not Found: /favicon.ico
Not Found: /static/js/bootstrap.min.js
Not Found: /static/bootflat/css/bootflat.min.css
Not Found: /static/css/bootstrap.min.css
Not Found: /static/js/jquery.min.js
Not Found: /favicon.ico
Not Found: /static/bootflat/css/bootflat.min.css
Not Found: /static/css/bootstrap.min.css
Not Found: /static/css/font-awesome.min.css
Not Found: /static/css/bootstrap-select.min.css
Not Found: /static/css/perfect-scrollbar.min.css
Not Found: /static/css/amaran.min.css
Not Found: /static/css/animate.min.css
Not Found: /static/css/themes/tooltipster-shadow.css
Not Found: /static/css/tooltipster.css
Not Found: /static/js/bootstrap.min.js
Not Found: /static/js/jquery.hotkeys.js
Not Found: /static/js/typeahead.js
Not Found: /static/js/jquery.min.js
Not Found: /static/js/bootstrap-select.js
Not Found: /static/js/bootbox.min.js
Not Found: /static/js/lang.ru.js
Not Found: /static/js/perfect-scrollbar.jquery.min.js
Not Found: /static/js/jquery-ui.min.js
Not Found: /static/js/jquery.isloading.min.js
Not Found: /static/js/jquery.scrollTo.js
Not Found: /static/bootflat/js/jquery.fs.selecter.min.js
Not Found: /static/bootflat/js/jquery.fs.stepper.min.js
Not Found: /static/bootflat/js/icheck.min.js
Not Found: /static/js/jquery.amaran.min.js
Not Found: /static/js/jquery.tooltipster.min.js
Not Found: /static/js/jquery.floatThead.min.js
Not Found: /static/fonts/OpenSans/OpenSans-Regular.ttf
Not Found: /static/fonts/OpenSans/OpenSans-Bold.ttf
Not Found: /static/css/bootstrap.min.css
Not Found: /static/bootflat/css/bootflat.min.css
Not Found: /static/css/font-awesome.min.css
Not Found: /static/css/bootstrap-select.min.css
Not Found: /static/css/perfect-scrollbar.min.css
Not Found: /static/css/tooltipster.css
Not Found: /static/css/amaran.min.css
Not Found: /static/css/themes/tooltipster-shadow.css
Not Found: /static/css/animate.min.css
Not Found: /static/js/bootstrap-datepicker.min.js
Not Found: /static/js/jquery.min.js
Not Found: /static/js/bootstrap.min.js
Not Found: /static/js/jquery.tablesorter.min.js
Not Found: /static/locales/bootstrap-datepicker.ru.min.js
Not Found: /static/js/jquery.hotkeys.js
Not Found: /static/js/typeahead.js
Not Found: /static/js/bootstrap-select.js
Not Found: /static/js/bootbox.min.js
Not Found: /static/js/lang.ru.js
Not Found: /static/js/perfect-scrollbar.jquery.min.js
Not Found: /static/js/jquery-ui.min.js
Not Found: /static/js/jquery.isloading.min.js
Not Found: /static/js/jquery.scrollTo.js
Not Found: /static/bootflat/js/jquery.fs.selecter.min.js
Not Found: /static/bootflat/js/jquery.fs.stepper.min.js
Not Found: /static/bootflat/js/icheck.min.js
Not Found: /static/js/jquery.amaran.min.js
Not Found: /static/js/jquery.tooltipster.min.js
Not Found: /static/js/jquery.floatThead.min.js
Not Found: /static/fonts/OpenSans/OpenSans-Regular.ttf
Not Found: /static/fonts/OpenSans/OpenSans-Bold.ttf
Not Found: /static/css/bootstrap.min.css
Not Found: /static/css/bootstrap-select.min.css
Not Found: /static/css/perfect-scrollbar.min.css
Not Found: /static/bootflat/css/bootflat.min.css
Not Found: /static/css/font-awesome.min.css
Not Found: /static/css/amaran.min.css
Not Found: /static/css/animate.min.css
Not Found: /static/css/tooltipster.css
Not Found: /static/css/themes/tooltipster-shadow.css
Not Found: /static/css/bootstrap.min.css
Not Found: /static/bootflat/css/bootflat.min.css
Not Found: /static/css/font-awesome.min.css
Not Found: /static/css/bootstrap-select.min.css
Not Found: /static/css/perfect-scrollbar.min.css
Not Found: /static/css/amaran.min.css
Not Found: /static/css/animate.min.css
Not Found: /static/css/tooltipster.css
Not Found: /static/css/themes/tooltipster-shadow.css
Not Found: /static/js/jquery.min.js
Not Found: /static/js/bootstrap.min.js
Not Found: /static/js/jquery.hotkeys.js
Not Found: /static/js/typeahead.js
Not Found: /static/js/bootstrap-select.js
Not Found: /static/js/bootbox.min.js
Not Found: /static/js/lang.ru.js
Not Found: /static/js/perfect-scrollbar.jquery.min.js
Not Found: /static/js/jquery-ui.min.js
Not Found: /static/js/jquery.isloading.min.js
Not Found: /static/js/jquery.scrollTo.js
Not Found: /static/bootflat/js/jquery.fs.selecter.min.js
Not Found: /static/bootflat/js/jquery.fs.stepper.min.js
Not Found: /static/bootflat/js/icheck.min.js
Not Found: /static/js/jquery.amaran.min.js
Not Found: /static/js/jquery.tooltipster.min.js
Not Found: /static/js/jquery.floatThead.min.js
Not Found: /static/js/bootstrap-datepicker.min.js
Not Found: /static/js/jquery.tablesorter.min.js
Not Found: /static/locales/bootstrap-datepicker.ru.min.js
Not Found: /static/fonts/OpenSans/OpenSans-Regular.ttf
Not Found: /static/fonts/OpenSans/OpenSans-Bold.ttf
Not Found: /favicon.ico
Not Found: /favicon.ico
Not Found: /favicon.ico
Not Found: /favicon.ico
Not Found: /favicon.ico
Internal Server Error: /directory/researches/list
Traceback (most recent call last):
  File "/usr/local/lib/python3.4/dist-packages/django/template/base.py", line 817, in _resolve_lookup
    current = current[bit]
TypeError: 'CachalotPanel' object is not subscriptable

During handling of the above exception, another exception occurred:

Traceback (most recent call last):
  File "/usr/local/lib/python3.4/dist-packages/django/core/handlers/base.py", line 223, in get_response
    response = middleware_method(request, response)
  File "/usr/local/lib/python3.4/dist-packages/debug_panel/middleware.py", line 65, in process_response
    cache.set(cache_key, toolbar.render_toolbar())
  File "/usr/local/lib/python3.4/dist-packages/debug_toolbar/toolbar.py", line 64, in render_toolbar
    return render_to_string('debug_toolbar/base.html', context)
  File "/usr/local/lib/python3.4/dist-packages/django/template/loader.py", line 99, in render_to_string
    return template.render(context, request)
  File "/usr/local/lib/python3.4/dist-packages/django/template/backends/django.py", line 74, in render
    return self.template.render(context)
  File "/usr/local/lib/python3.4/dist-packages/django/template/base.py", line 209, in render
    return self._render(context)
  File "/usr/local/lib/python3.4/dist-packages/django/test/utils.py", line 96, in instrumented_test_render
    return self.nodelist.render(context)
  File "/usr/local/lib/python3.4/dist-packages/django/template/base.py", line 903, in render
    bit = self.render_node(node, context)
  File "/usr/local/lib/python3.4/dist-packages/django/template/debug.py", line 79, in render_node
    return node.render(context)
  File "/usr/local/lib/python3.4/dist-packages/django/template/defaulttags.py", line 217, in render
    nodelist.append(node.render(context))
  File "/usr/local/lib/python3.4/dist-packages/django/template/defaulttags.py", line 329, in render
    return nodelist.render(context)
  File "/usr/local/lib/python3.4/dist-packages/django/template/base.py", line 903, in render
    bit = self.render_node(node, context)
  File "/usr/local/lib/python3.4/dist-packages/django/template/debug.py", line 79, in render_node
    return node.render(context)
  File "/usr/local/lib/python3.4/dist-packages/django/template/defaulttags.py", line 329, in render
    return nodelist.render(context)
  File "/usr/local/lib/python3.4/dist-packages/django/template/base.py", line 903, in render
    bit = self.render_node(node, context)
  File "/usr/local/lib/python3.4/dist-packages/django/template/debug.py", line 79, in render_node
    return node.render(context)
  File "/usr/local/lib/python3.4/dist-packages/django/template/debug.py", line 89, in render
    output = self.filter_expression.resolve(context)
  File "/usr/local/lib/python3.4/dist-packages/django/template/base.py", line 647, in resolve
    obj = self.var.resolve(context)
  File "/usr/local/lib/python3.4/dist-packages/django/template/base.py", line 787, in resolve
    value = self._resolve_lookup(context)
  File "/usr/local/lib/python3.4/dist-packages/django/template/base.py", line 825, in _resolve_lookup
    current = getattr(current, bit)
  File "/usr/local/lib/python3.4/dist-packages/debug_toolbar/panels/__init__.py", line 96, in content
    return render_to_string(self.template, self.get_stats())
  File "/usr/local/lib/python3.4/dist-packages/django/template/loader.py", line 98, in render_to_string
    template = get_template(template_name, using=using)
  File "/usr/local/lib/python3.4/dist-packages/django/template/loader.py", line 46, in get_template
    raise TemplateDoesNotExist(template_name)
django.template.base.TemplateDoesNotExist: cachalot/panel.html
Internal Server Error: /directions/ajax/save
Traceback (most recent call last):
  File "/usr/local/lib/python3.4/dist-packages/django/template/base.py", line 817, in _resolve_lookup
    current = current[bit]
TypeError: 'CachalotPanel' object is not subscriptable

During handling of the above exception, another exception occurred:

Traceback (most recent call last):
  File "/usr/local/lib/python3.4/dist-packages/django/core/handlers/base.py", line 223, in get_response
    response = middleware_method(request, response)
  File "/usr/local/lib/python3.4/dist-packages/debug_panel/middleware.py", line 65, in process_response
    cache.set(cache_key, toolbar.render_toolbar())
  File "/usr/local/lib/python3.4/dist-packages/debug_toolbar/toolbar.py", line 64, in render_toolbar
    return render_to_string('debug_toolbar/base.html', context)
  File "/usr/local/lib/python3.4/dist-packages/django/template/loader.py", line 99, in render_to_string
    return template.render(context, request)
  File "/usr/local/lib/python3.4/dist-packages/django/template/backends/django.py", line 74, in render
    return self.template.render(context)
  File "/usr/local/lib/python3.4/dist-packages/django/template/base.py", line 209, in render
    return self._render(context)
  File "/usr/local/lib/python3.4/dist-packages/django/test/utils.py", line 96, in instrumented_test_render
    return self.nodelist.render(context)
  File "/usr/local/lib/python3.4/dist-packages/django/template/base.py", line 903, in render
    bit = self.render_node(node, context)
  File "/usr/local/lib/python3.4/dist-packages/django/template/debug.py", line 79, in render_node
    return node.render(context)
  File "/usr/local/lib/python3.4/dist-packages/django/template/defaulttags.py", line 217, in render
    nodelist.append(node.render(context))
  File "/usr/local/lib/python3.4/dist-packages/django/template/defaulttags.py", line 329, in render
    return nodelist.render(context)
  File "/usr/local/lib/python3.4/dist-packages/django/template/base.py", line 903, in render
    bit = self.render_node(node, context)
  File "/usr/local/lib/python3.4/dist-packages/django/template/debug.py", line 79, in render_node
    return node.render(context)
  File "/usr/local/lib/python3.4/dist-packages/django/template/defaulttags.py", line 329, in render
    return nodelist.render(context)
  File "/usr/local/lib/python3.4/dist-packages/django/template/base.py", line 903, in render
    bit = self.render_node(node, context)
  File "/usr/local/lib/python3.4/dist-packages/django/template/debug.py", line 79, in render_node
    return node.render(context)
  File "/usr/local/lib/python3.4/dist-packages/django/template/debug.py", line 89, in render
    output = self.filter_expression.resolve(context)
  File "/usr/local/lib/python3.4/dist-packages/django/template/base.py", line 647, in resolve
    obj = self.var.resolve(context)
  File "/usr/local/lib/python3.4/dist-packages/django/template/base.py", line 787, in resolve
    value = self._resolve_lookup(context)
  File "/usr/local/lib/python3.4/dist-packages/django/template/base.py", line 825, in _resolve_lookup
    current = getattr(current, bit)
  File "/usr/local/lib/python3.4/dist-packages/debug_toolbar/panels/__init__.py", line 96, in content
    return render_to_string(self.template, self.get_stats())
  File "/usr/local/lib/python3.4/dist-packages/django/template/loader.py", line 98, in render_to_string
    template = get_template(template_name, using=using)
  File "/usr/local/lib/python3.4/dist-packages/django/template/loader.py", line 46, in get_template
    raise TemplateDoesNotExist(template_name)
django.template.base.TemplateDoesNotExist: cachalot/panel.html
Not Found: /favicon.ico
Not Found: /favicon.ico
Not Found: /favicon.ico
Not Found: /favicon.ico
Not Found: /favicon.ico
Not Found: /favicon.ico
Not Found: /favicon.ico
Not Found: /favicon.ico
Internal Server Error: /results/pdf
Traceback (most recent call last):
  File "/usr/local/lib/python3.4/dist-packages/django/core/handlers/base.py", line 132, in get_response
    response = wrapped_callback(request, *callback_args, **callback_kwargs)
  File "/usr/local/lib/python3.4/dist-packages/django/contrib/auth/decorators.py", line 22, in _wrapped_view
    return view_func(request, *args, **kwargs)
  File "/webapps/lis2/results/views.py", line 264, in result_print
    draw_obj(c, obj, i, request.user.doctorprofile)
  File "/webapps/lis2/results/views.py", line 413, in draw_obj
    styleSheet["BodyText"]))
  File "/usr/local/lib/python3.4/dist-packages/reportlab/platypus/paragraph.py", line 1042, in __init__
    self._setup(text, style, bulletText or getattr(style,'bulletText',None), frags, cleanBlockQuotedText)
  File "/usr/local/lib/python3.4/dist-packages/reportlab/platypus/paragraph.py", line 1064, in _setup
    style, frags, bulletTextFrags = _parser.parse(text,style)
  File "/usr/local/lib/python3.4/dist-packages/reportlab/platypus/paraparser.py", line 1167, in parse
    annotateException('\nparagraph text %s caused exception' % ascii(text))
  File "/usr/local/lib/python3.4/dist-packages/reportlab/lib/utils.py", line 1381, in annotateException
    rl_reraise(t,v,b)
  File "/usr/local/lib/python3.4/dist-packages/reportlab/lib/utils.py", line 138, in rl_reraise
    raise v
  File "/usr/local/lib/python3.4/dist-packages/reportlab/platypus/paraparser.py", line 1165, in parse
    self.feed(text)
  File "/usr/lib/python3.4/html/parser.py", line 165, in feed
    self.goahead(0)
  File "/usr/lib/python3.4/html/parser.py", line 224, in goahead
    k = self.parse_endtag(i)
  File "/usr/lib/python3.4/html/parser.py", line 500, in parse_endtag
    self.handle_endtag(elem.lower())
  File "/usr/local/lib/python3.4/dist-packages/reportlab/platypus/paraparser.py", line 1201, in handle_endtag
    end()
  File "/usr/local/lib/python3.4/dist-packages/reportlab/platypus/paraparser.py", line 786, in end_font
    self._pop('font')
  File "/usr/local/lib/python3.4/dist-packages/reportlab/platypus/paraparser.py", line 1006, in _pop
    raise ValueError('Parse error: saw </%s> instead of expected </%s>' % (tag,frag.__tag__))
ValueError: Parse error: saw </font> instead of expected </br>
paragraph text '<para><font face="OpenSans" size="8">18-44 : 117-155<br>65-74 : 117-161<br>45-64 : 117-160</font></para>' caused exception
Internal Server Error: /results/pdf
Traceback (most recent call last):
  File "/usr/local/lib/python3.4/dist-packages/django/core/handlers/base.py", line 132, in get_response
    response = wrapped_callback(request, *callback_args, **callback_kwargs)
  File "/usr/local/lib/python3.4/dist-packages/django/contrib/auth/decorators.py", line 22, in _wrapped_view
    return view_func(request, *args, **kwargs)
  File "/webapps/lis2/results/views.py", line 264, in result_print
    draw_obj(c, obj, i, request.user.doctorprofile)
  File "/webapps/lis2/results/views.py", line 413, in draw_obj
    styleSheet["BodyText"]))
  File "/usr/local/lib/python3.4/dist-packages/reportlab/platypus/paragraph.py", line 1042, in __init__
    self._setup(text, style, bulletText or getattr(style,'bulletText',None), frags, cleanBlockQuotedText)
  File "/usr/local/lib/python3.4/dist-packages/reportlab/platypus/paragraph.py", line 1064, in _setup
    style, frags, bulletTextFrags = _parser.parse(text,style)
  File "/usr/local/lib/python3.4/dist-packages/reportlab/platypus/paraparser.py", line 1167, in parse
    annotateException('\nparagraph text %s caused exception' % ascii(text))
  File "/usr/local/lib/python3.4/dist-packages/reportlab/lib/utils.py", line 1381, in annotateException
    rl_reraise(t,v,b)
  File "/usr/local/lib/python3.4/dist-packages/reportlab/lib/utils.py", line 138, in rl_reraise
    raise v
  File "/usr/local/lib/python3.4/dist-packages/reportlab/platypus/paraparser.py", line 1165, in parse
    self.feed(text)
  File "/usr/lib/python3.4/html/parser.py", line 165, in feed
    self.goahead(0)
  File "/usr/lib/python3.4/html/parser.py", line 224, in goahead
    k = self.parse_endtag(i)
  File "/usr/lib/python3.4/html/parser.py", line 500, in parse_endtag
    self.handle_endtag(elem.lower())
  File "/usr/local/lib/python3.4/dist-packages/reportlab/platypus/paraparser.py", line 1201, in handle_endtag
    end()
  File "/usr/local/lib/python3.4/dist-packages/reportlab/platypus/paraparser.py", line 786, in end_font
    self._pop('font')
  File "/usr/local/lib/python3.4/dist-packages/reportlab/platypus/paraparser.py", line 1006, in _pop
    raise ValueError('Parse error: saw </%s> instead of expected </%s>' % (tag,frag.__tag__))
ValueError: Parse error: saw </font> instead of expected </br>
paragraph text '<para><font face="OpenSans" size="8">18-44 : 117-155<br>65-74 : 117-161<br>45-64 : 117-160</font></para>' caused exception
Not Found: /favicon.ico
Internal Server Error: /results/pdf
Traceback (most recent call last):
  File "/usr/local/lib/python3.4/dist-packages/django/core/handlers/base.py", line 132, in get_response
    response = wrapped_callback(request, *callback_args, **callback_kwargs)
  File "/usr/local/lib/python3.4/dist-packages/django/contrib/auth/decorators.py", line 22, in _wrapped_view
    return view_func(request, *args, **kwargs)
  File "/webapps/lis2/results/views.py", line 264, in result_print
    draw_obj(c, obj, i, request.user.doctorprofile)
  File "/webapps/lis2/results/views.py", line 359, in draw_obj
    tmp.append(Paragraph('<font face="OpenSans" align="right" size="8">' + result + "</font>", styleSheet["BodyText"]))
  File "/usr/local/lib/python3.4/dist-packages/reportlab/platypus/paragraph.py", line 1042, in __init__
    self._setup(text, style, bulletText or getattr(style,'bulletText',None), frags, cleanBlockQuotedText)
  File "/usr/local/lib/python3.4/dist-packages/reportlab/platypus/paragraph.py", line 1067, in _setup
    % (_parser.errors[0],text[:min(30,len(text))]))
ValueError: xml parser error (invalid attribute name align) in paragraph beginning
'<font face="OpenSans" align="r'
Internal Server Error: /results/pdf
Traceback (most recent call last):
  File "/usr/local/lib/python3.4/dist-packages/django/core/handlers/base.py", line 132, in get_response
    response = wrapped_callback(request, *callback_args, **callback_kwargs)
  File "/usr/local/lib/python3.4/dist-packages/django/contrib/auth/decorators.py", line 22, in _wrapped_view
    return view_func(request, *args, **kwargs)
  File "/webapps/lis2/results/views.py", line 264, in result_print
    draw_obj(c, obj, i, request.user.doctorprofile)
  File "/webapps/lis2/results/views.py", line 359, in draw_obj
    tmp.append(Paragraph('<font face="OpenSans" alignment="right" size="8">' + result + "</font>", styleSheet["BodyText"]))
  File "/usr/local/lib/python3.4/dist-packages/reportlab/platypus/paragraph.py", line 1042, in __init__
    self._setup(text, style, bulletText or getattr(style,'bulletText',None), frags, cleanBlockQuotedText)
  File "/usr/local/lib/python3.4/dist-packages/reportlab/platypus/paragraph.py", line 1067, in _setup
    % (_parser.errors[0],text[:min(30,len(text))]))
ValueError: xml parser error (invalid attribute name alignment) in paragraph beginning
'<font face="OpenSans" alignmen'
Internal Server Error: /results/pdf
Traceback (most recent call last):
  File "/usr/local/lib/python3.4/dist-packages/django/core/handlers/base.py", line 132, in get_response
    response = wrapped_callback(request, *callback_args, **callback_kwargs)
  File "/usr/local/lib/python3.4/dist-packages/django/contrib/auth/decorators.py", line 22, in _wrapped_view
    return view_func(request, *args, **kwargs)
  File "/webapps/lis2/results/views.py", line 264, in result_print
    draw_obj(c, obj, i, request.user.doctorprofile)
  File "/webapps/lis2/results/views.py", line 359, in draw_obj
    tmp.append(Paragraph('<font face="OpenSans" alignment="right" size="8">' + result + "</font>", styleSheet["BodyText"]))
  File "/usr/local/lib/python3.4/dist-packages/reportlab/platypus/paragraph.py", line 1042, in __init__
    self._setup(text, style, bulletText or getattr(style,'bulletText',None), frags, cleanBlockQuotedText)
  File "/usr/local/lib/python3.4/dist-packages/reportlab/platypus/paragraph.py", line 1067, in _setup
    % (_parser.errors[0],text[:min(30,len(text))]))
ValueError: xml parser error (invalid attribute name alignment) in paragraph beginning
'<font face="OpenSans" alignmen'
Internal Server Error: /results/pdf
Traceback (most recent call last):
  File "/usr/local/lib/python3.4/dist-packages/django/core/handlers/base.py", line 132, in get_response
    response = wrapped_callback(request, *callback_args, **callback_kwargs)
  File "/usr/local/lib/python3.4/dist-packages/django/contrib/auth/decorators.py", line 22, in _wrapped_view
    return view_func(request, *args, **kwargs)
  File "/webapps/lis2/results/views.py", line 264, in result_print
    draw_obj(c, obj, i, request.user.doctorprofile)
  File "/webapps/lis2/results/views.py", line 359, in draw_obj
    tmp.append(Paragraph('<font face="OpenSans" alignment="right" size="8">' + result + "</font>", styleSheet["BodyText"]))
  File "/usr/local/lib/python3.4/dist-packages/reportlab/platypus/paragraph.py", line 1042, in __init__
    self._setup(text, style, bulletText or getattr(style,'bulletText',None), frags, cleanBlockQuotedText)
  File "/usr/local/lib/python3.4/dist-packages/reportlab/platypus/paragraph.py", line 1067, in _setup
    % (_parser.errors[0],text[:min(30,len(text))]))
ValueError: xml parser error (invalid attribute name alignment) in paragraph beginning
'<font face="OpenSans" alignmen'
Internal Server Error: /results/pdf
Traceback (most recent call last):
  File "/usr/local/lib/python3.4/dist-packages/django/core/handlers/base.py", line 132, in get_response
    response = wrapped_callback(request, *callback_args, **callback_kwargs)
  File "/usr/local/lib/python3.4/dist-packages/django/contrib/auth/decorators.py", line 22, in _wrapped_view
    return view_func(request, *args, **kwargs)
  File "/webapps/lis2/results/views.py", line 264, in result_print
    draw_obj(c, obj, i, request.user.doctorprofile)
  File "/webapps/lis2/results/views.py", line 359, in draw_obj
    tmp.append(Paragraph('<font face="OpenSans" alignment="right" size="8">' + result + "</font>", styleSheet["BodyText"]))
  File "/usr/local/lib/python3.4/dist-packages/reportlab/platypus/paragraph.py", line 1042, in __init__
    self._setup(text, style, bulletText or getattr(style,'bulletText',None), frags, cleanBlockQuotedText)
  File "/usr/local/lib/python3.4/dist-packages/reportlab/platypus/paragraph.py", line 1067, in _setup
    % (_parser.errors[0],text[:min(30,len(text))]))
ValueError: xml parser error (invalid attribute name alignment) in paragraph beginning
'<font face="OpenSans" alignmen'
Internal Server Error: /results/pdf
Traceback (most recent call last):
  File "/usr/local/lib/python3.4/dist-packages/django/core/handlers/base.py", line 132, in get_response
    response = wrapped_callback(request, *callback_args, **callback_kwargs)
  File "/usr/local/lib/python3.4/dist-packages/django/contrib/auth/decorators.py", line 22, in _wrapped_view
    return view_func(request, *args, **kwargs)
  File "/webapps/lis2/results/views.py", line 264, in result_print
    draw_obj(c, obj, i, request.user.doctorprofile)
  File "/webapps/lis2/results/views.py", line 359, in draw_obj
    tmp.append(Paragraph('<font face="OpenSans" alignment="right" size="8">' + result + "</font>", styleSheet["BodyText"]))
  File "/usr/local/lib/python3.4/dist-packages/reportlab/platypus/paragraph.py", line 1042, in __init__
    self._setup(text, style, bulletText or getattr(style,'bulletText',None), frags, cleanBlockQuotedText)
  File "/usr/local/lib/python3.4/dist-packages/reportlab/platypus/paragraph.py", line 1067, in _setup
    % (_parser.errors[0],text[:min(30,len(text))]))
ValueError: xml parser error (invalid attribute name alignment) in paragraph beginning
'<font face="OpenSans" alignmen'
Internal Server Error: /results/pdf
Traceback (most recent call last):
  File "/usr/local/lib/python3.4/dist-packages/django/core/handlers/base.py", line 132, in get_response
    response = wrapped_callback(request, *callback_args, **callback_kwargs)
  File "/usr/local/lib/python3.4/dist-packages/django/contrib/auth/decorators.py", line 22, in _wrapped_view
    return view_func(request, *args, **kwargs)
  File "/webapps/lis2/results/views.py", line 264, in result_print
    draw_obj(c, obj, i, request.user.doctorprofile)
  File "/webapps/lis2/results/views.py", line 359, in draw_obj
    tmp.append(Paragraph('<font face="OpenSans" size="8"><para alignment="right">' + result + "</para></font>", styleSheet["BodyText"]))
  File "/usr/local/lib/python3.4/dist-packages/reportlab/platypus/paragraph.py", line 1042, in __init__
    self._setup(text, style, bulletText or getattr(style,'bulletText',None), frags, cleanBlockQuotedText)
  File "/usr/local/lib/python3.4/dist-packages/reportlab/platypus/paragraph.py", line 1064, in _setup
    style, frags, bulletTextFrags = _parser.parse(text,style)
  File "/usr/local/lib/python3.4/dist-packages/reportlab/platypus/paraparser.py", line 1167, in parse
    annotateException('\nparagraph text %s caused exception' % ascii(text))
  File "/usr/local/lib/python3.4/dist-packages/reportlab/lib/utils.py", line 1381, in annotateException
    rl_reraise(t,v,b)
  File "/usr/local/lib/python3.4/dist-packages/reportlab/lib/utils.py", line 138, in rl_reraise
    raise v
  File "/usr/local/lib/python3.4/dist-packages/reportlab/platypus/paraparser.py", line 1165, in parse
    self.feed(text)
  File "/usr/lib/python3.4/html/parser.py", line 165, in feed
    self.goahead(0)
  File "/usr/lib/python3.4/html/parser.py", line 224, in goahead
    k = self.parse_endtag(i)
  File "/usr/lib/python3.4/html/parser.py", line 500, in parse_endtag
    self.handle_endtag(elem.lower())
  File "/usr/local/lib/python3.4/dist-packages/reportlab/platypus/paraparser.py", line 1201, in handle_endtag
    end()
  File "/usr/local/lib/python3.4/dist-packages/reportlab/platypus/paraparser.py", line 786, in end_font
    self._pop('font')
  File "/usr/local/lib/python3.4/dist-packages/reportlab/platypus/paraparser.py", line 1004, in _pop
    frag = self._stack.pop()
IndexError: pop from empty list
paragraph text '<para><font face="OpenSans" size="8"><para alignment="right">9 O/oo</para></font></para>' caused exception
Internal Server Error: /results/pdf
Traceback (most recent call last):
  File "/usr/local/lib/python3.4/dist-packages/django/core/handlers/base.py", line 132, in get_response
    response = wrapped_callback(request, *callback_args, **callback_kwargs)
  File "/usr/local/lib/python3.4/dist-packages/django/contrib/auth/decorators.py", line 22, in _wrapped_view
    return view_func(request, *args, **kwargs)
  File "/webapps/lis2/results/views.py", line 264, in result_print
    draw_obj(c, obj, i, request.user.doctorprofile)
  File "/webapps/lis2/results/views.py", line 359, in draw_obj
    tmp.append(Paragraph('<font face="OpenSans" size="8"><para alignment="right">' + result + "</para></font>", styleSheet["BodyText"]))
  File "/usr/local/lib/python3.4/dist-packages/reportlab/platypus/paragraph.py", line 1042, in __init__
    self._setup(text, style, bulletText or getattr(style,'bulletText',None), frags, cleanBlockQuotedText)
  File "/usr/local/lib/python3.4/dist-packages/reportlab/platypus/paragraph.py", line 1064, in _setup
    style, frags, bulletTextFrags = _parser.parse(text,style)
  File "/usr/local/lib/python3.4/dist-packages/reportlab/platypus/paraparser.py", line 1167, in parse
    annotateException('\nparagraph text %s caused exception' % ascii(text))
  File "/usr/local/lib/python3.4/dist-packages/reportlab/lib/utils.py", line 1381, in annotateException
    rl_reraise(t,v,b)
  File "/usr/local/lib/python3.4/dist-packages/reportlab/lib/utils.py", line 138, in rl_reraise
    raise v
  File "/usr/local/lib/python3.4/dist-packages/reportlab/platypus/paraparser.py", line 1165, in parse
    self.feed(text)
  File "/usr/lib/python3.4/html/parser.py", line 165, in feed
    self.goahead(0)
  File "/usr/lib/python3.4/html/parser.py", line 224, in goahead
    k = self.parse_endtag(i)
  File "/usr/lib/python3.4/html/parser.py", line 500, in parse_endtag
    self.handle_endtag(elem.lower())
  File "/usr/local/lib/python3.4/dist-packages/reportlab/platypus/paraparser.py", line 1201, in handle_endtag
    end()
  File "/usr/local/lib/python3.4/dist-packages/reportlab/platypus/paraparser.py", line 786, in end_font
    self._pop('font')
  File "/usr/local/lib/python3.4/dist-packages/reportlab/platypus/paraparser.py", line 1004, in _pop
    frag = self._stack.pop()
IndexError: pop from empty list
paragraph text '<para><font face="OpenSans" size="8"><para alignment="right">9 O/oo</para></font></para>' caused exception
Not Found: /favicon.ico
Internal Server Error: /researches/get/one
Traceback (most recent call last):
  File "/usr/local/lib/python3.4/dist-packages/django/core/handlers/base.py", line 132, in get_response
    response = wrapped_callback(request, *callback_args, **callback_kwargs)
  File "/usr/local/lib/python3.4/dist-packages/django/contrib/auth/decorators.py", line 22, in _wrapped_view
    return view_func(request, *args, **kwargs)
  File "/webapps/lis2/researches/views.py", line 54, in researches_get_one
    res["fractions"].append(
AttributeError: 'dict' object has no attribute 'append'
Internal Server Error: /researches/get/one
Traceback (most recent call last):
  File "/usr/local/lib/python3.4/dist-packages/django/core/handlers/base.py", line 132, in get_response
    response = wrapped_callback(request, *callback_args, **callback_kwargs)
  File "/usr/local/lib/python3.4/dist-packages/django/contrib/auth/decorators.py", line 22, in _wrapped_view
    return view_func(request, *args, **kwargs)
  File "/webapps/lis2/researches/views.py", line 54, in researches_get_one
    res["fractions"].append(
AttributeError: 'dict' object has no attribute 'append'
Internal Server Error: /researches/get/one
Traceback (most recent call last):
  File "/usr/local/lib/python3.4/dist-packages/django/core/handlers/base.py", line 132, in get_response
    response = wrapped_callback(request, *callback_args, **callback_kwargs)
  File "/usr/local/lib/python3.4/dist-packages/django/contrib/auth/decorators.py", line 22, in _wrapped_view
    return view_func(request, *args, **kwargs)
  File "/webapps/lis2/researches/views.py", line 54, in researches_get_one
    res["fractions"].append(
AttributeError: 'dict' object has no attribute 'append'
Not Found: /favicon.ico
Not Found: /favicon.ico
Not Found: /favicon.ico
Internal Server Error: /tubes/get
Traceback (most recent call last):
  File "/usr/local/lib/python3.4/dist-packages/django/core/handlers/base.py", line 132, in get_response
    response = wrapped_callback(request, *callback_args, **callback_kwargs)
  File "/usr/local/lib/python3.4/dist-packages/django/contrib/auth/decorators.py", line 22, in _wrapped_view
    return view_func(request, *args, **kwargs)
  File "/webapps/lis2/receivematerial/views.py", line 51, in tubes_get
    subgroup_lab = Subgroups.objects.get(pk=request.GET["subgroup"])
  File "/usr/local/lib/python3.4/dist-packages/django/db/models/manager.py", line 127, in manager_method
    return getattr(self.get_queryset(), name)(*args, **kwargs)
  File "/usr/local/lib/python3.4/dist-packages/django/db/models/query.py", line 325, in get
    clone = self.filter(*args, **kwargs)
  File "/usr/local/lib/python3.4/dist-packages/django/db/models/query.py", line 679, in filter
    return self._filter_or_exclude(False, *args, **kwargs)
  File "/usr/local/lib/python3.4/dist-packages/django/db/models/query.py", line 697, in _filter_or_exclude
    clone.query.add_q(Q(*args, **kwargs))
  File "/usr/local/lib/python3.4/dist-packages/django/db/models/sql/query.py", line 1309, in add_q
    clause, require_inner = self._add_q(where_part, self.used_aliases)
  File "/usr/local/lib/python3.4/dist-packages/django/db/models/sql/query.py", line 1337, in _add_q
    allow_joins=allow_joins, split_subq=split_subq,
  File "/usr/local/lib/python3.4/dist-packages/django/db/models/sql/query.py", line 1208, in build_filter
    condition = self.build_lookup(lookups, col, value)
  File "/usr/local/lib/python3.4/dist-packages/django/db/models/sql/query.py", line 1101, in build_lookup
    return final_lookup(lhs, rhs)
  File "/usr/local/lib/python3.4/dist-packages/django/db/models/lookups.py", line 101, in __init__
    self.rhs = self.get_prep_lookup()
  File "/usr/local/lib/python3.4/dist-packages/django/db/models/lookups.py", line 139, in get_prep_lookup
    return self.lhs.output_field.get_prep_lookup(self.lookup_name, self.rhs)
  File "/usr/local/lib/python3.4/dist-packages/django/db/models/fields/__init__.py", line 727, in get_prep_lookup
    return self.get_prep_value(value)
  File "/usr/local/lib/python3.4/dist-packages/django/db/models/fields/__init__.py", line 985, in get_prep_value
    return int(value)
ValueError: invalid literal for int() with base 10: 'undefined'
Internal Server Error: /directions/get/one
Traceback (most recent call last):
  File "/usr/local/lib/python3.4/dist-packages/django/utils/datastructures.py", line 320, in __getitem__
    list_ = super(MultiValueDict, self).__getitem__(key)
KeyError: 'check'

During handling of the above exception, another exception occurred:

Traceback (most recent call last):
  File "/usr/local/lib/python3.4/dist-packages/django/core/handlers/base.py", line 132, in get_response
    response = wrapped_callback(request, *callback_args, **callback_kwargs)
  File "/usr/local/lib/python3.4/dist-packages/django/contrib/auth/decorators.py", line 22, in _wrapped_view
    return view_func(request, *args, **kwargs)
  File "/webapps/lis2/directions/views.py", line 362, in get_one_dir
    if not request.GET["check"]:
  File "/usr/local/lib/python3.4/dist-packages/django/utils/datastructures.py", line 322, in __getitem__
    raise MultiValueDictKeyError(repr(key))
django.utils.datastructures.MultiValueDictKeyError: "'check'"
Internal Server Error: /directions/get/one
Traceback (most recent call last):
  File "/usr/local/lib/python3.4/dist-packages/django/utils/datastructures.py", line 320, in __getitem__
    list_ = super(MultiValueDict, self).__getitem__(key)
KeyError: 'check'

During handling of the above exception, another exception occurred:

Traceback (most recent call last):
  File "/usr/local/lib/python3.4/dist-packages/django/core/handlers/base.py", line 132, in get_response
    response = wrapped_callback(request, *callback_args, **callback_kwargs)
  File "/usr/local/lib/python3.4/dist-packages/django/contrib/auth/decorators.py", line 22, in _wrapped_view
    return view_func(request, *args, **kwargs)
  File "/webapps/lis2/directions/views.py", line 362, in get_one_dir
    if not request.GET["check"]:
  File "/usr/local/lib/python3.4/dist-packages/django/utils/datastructures.py", line 322, in __getitem__
    raise MultiValueDictKeyError(repr(key))
django.utils.datastructures.MultiValueDictKeyError: "'check'"
Internal Server Error: /directions/get/one
Traceback (most recent call last):
  File "/usr/local/lib/python3.4/dist-packages/django/utils/datastructures.py", line 320, in __getitem__
    list_ = super(MultiValueDict, self).__getitem__(key)
KeyError: 'check'

During handling of the above exception, another exception occurred:

Traceback (most recent call last):
  File "/usr/local/lib/python3.4/dist-packages/django/core/handlers/base.py", line 132, in get_response
    response = wrapped_callback(request, *callback_args, **callback_kwargs)
  File "/usr/local/lib/python3.4/dist-packages/django/contrib/auth/decorators.py", line 22, in _wrapped_view
    return view_func(request, *args, **kwargs)
  File "/webapps/lis2/directions/views.py", line 362, in get_one_dir
    if not request.GET["check"]:
  File "/usr/local/lib/python3.4/dist-packages/django/utils/datastructures.py", line 322, in __getitem__
    raise MultiValueDictKeyError(repr(key))
django.utils.datastructures.MultiValueDictKeyError: "'check'"
Internal Server Error: /directions/get/one
Traceback (most recent call last):
  File "/usr/local/lib/python3.4/dist-packages/django/utils/datastructures.py", line 320, in __getitem__
    list_ = super(MultiValueDict, self).__getitem__(key)
KeyError: 'check'

During handling of the above exception, another exception occurred:

Traceback (most recent call last):
  File "/usr/local/lib/python3.4/dist-packages/django/core/handlers/base.py", line 132, in get_response
    response = wrapped_callback(request, *callback_args, **callback_kwargs)
  File "/usr/local/lib/python3.4/dist-packages/django/contrib/auth/decorators.py", line 22, in _wrapped_view
    return view_func(request, *args, **kwargs)
  File "/webapps/lis2/directions/views.py", line 362, in get_one_dir
    if "check" not in request.GET.keys() and not request.GET["check"]:
  File "/usr/local/lib/python3.4/dist-packages/django/utils/datastructures.py", line 322, in __getitem__
    raise MultiValueDictKeyError(repr(key))
django.utils.datastructures.MultiValueDictKeyError: "'check'"
Internal Server Error: /direction/researches/update/history/print
Traceback (most recent call last):
  File "/usr/local/lib/python3.4/dist-packages/django/core/handlers/base.py", line 132, in get_response
    response = wrapped_callback(request, *callback_args, **callback_kwargs)
  File "/usr/local/lib/python3.4/dist-packages/django/contrib/auth/decorators.py", line 22, in _wrapped_view
    return view_func(request, *args, **kwargs)
  File "/webapps/lis2/directions/views.py", line 529, in print_history
    "time": v.time_get.astimezone(local_tz).strftime("%H:%M:%S"), "dir_id": iss[0].napravleniye.pk,
AttributeError: 'NoneType' object has no attribute 'astimezone'
Internal Server Error: /direction/researches/update/history/print
Traceback (most recent call last):
  File "/usr/local/lib/python3.4/dist-packages/django/core/handlers/base.py", line 132, in get_response
    response = wrapped_callback(request, *callback_args, **callback_kwargs)
  File "/usr/local/lib/python3.4/dist-packages/django/contrib/auth/decorators.py", line 22, in _wrapped_view
    return view_func(request, *args, **kwargs)
  File "/webapps/lis2/directions/views.py", line 529, in print_history
    "time": v.time_get.astimezone(local_tz).strftime("%H:%M:%S"), "dir_id": iss[0].napravleniye.pk,
AttributeError: 'NoneType' object has no attribute 'astimezone'
Internal Server Error: /direction/researches/update/history/print
Traceback (most recent call last):
  File "/usr/local/lib/python3.4/dist-packages/django/core/handlers/base.py", line 132, in get_response
    response = wrapped_callback(request, *callback_args, **callback_kwargs)
  File "/usr/local/lib/python3.4/dist-packages/django/contrib/auth/decorators.py", line 22, in _wrapped_view
    return view_func(request, *args, **kwargs)
  File "/webapps/lis2/directions/views.py", line 529, in print_history
    "time": v.time_get.astimezone(local_tz).strftime("%H:%M:%S"), "dir_id": iss[0].napravleniye.pk,
AttributeError: 'NoneType' object has no attribute 'astimezone'
Internal Server Error: /tubes/get
Traceback (most recent call last):
  File "/usr/local/lib/python3.4/dist-packages/django/core/handlers/base.py", line 132, in get_response
    response = wrapped_callback(request, *callback_args, **callback_kwargs)
  File "/usr/local/lib/python3.4/dist-packages/django/contrib/auth/decorators.py", line 22, in _wrapped_view
    return view_func(request, *args, **kwargs)
  File "/webapps/lis2/receivematerial/views.py", line 51, in tubes_get
    subgroup_lab = Subgroups.objects.get(pk=request.GET["subgroup"])
  File "/usr/local/lib/python3.4/dist-packages/django/db/models/manager.py", line 127, in manager_method
    return getattr(self.get_queryset(), name)(*args, **kwargs)
  File "/usr/local/lib/python3.4/dist-packages/django/db/models/query.py", line 325, in get
    clone = self.filter(*args, **kwargs)
  File "/usr/local/lib/python3.4/dist-packages/django/db/models/query.py", line 679, in filter
    return self._filter_or_exclude(False, *args, **kwargs)
  File "/usr/local/lib/python3.4/dist-packages/django/db/models/query.py", line 697, in _filter_or_exclude
    clone.query.add_q(Q(*args, **kwargs))
  File "/usr/local/lib/python3.4/dist-packages/django/db/models/sql/query.py", line 1309, in add_q
    clause, require_inner = self._add_q(where_part, self.used_aliases)
  File "/usr/local/lib/python3.4/dist-packages/django/db/models/sql/query.py", line 1337, in _add_q
    allow_joins=allow_joins, split_subq=split_subq,
  File "/usr/local/lib/python3.4/dist-packages/django/db/models/sql/query.py", line 1208, in build_filter
    condition = self.build_lookup(lookups, col, value)
  File "/usr/local/lib/python3.4/dist-packages/django/db/models/sql/query.py", line 1101, in build_lookup
    return final_lookup(lhs, rhs)
  File "/usr/local/lib/python3.4/dist-packages/django/db/models/lookups.py", line 101, in __init__
    self.rhs = self.get_prep_lookup()
  File "/usr/local/lib/python3.4/dist-packages/django/db/models/lookups.py", line 139, in get_prep_lookup
    return self.lhs.output_field.get_prep_lookup(self.lookup_name, self.rhs)
  File "/usr/local/lib/python3.4/dist-packages/django/db/models/fields/__init__.py", line 727, in get_prep_lookup
    return self.get_prep_value(value)
  File "/usr/local/lib/python3.4/dist-packages/django/db/models/fields/__init__.py", line 985, in get_prep_value
    return int(value)
ValueError: invalid literal for int() with base 10: 'undefined'
Not Found: /favicon.ico
Internal Server Error: /tubes/get
Traceback (most recent call last):
  File "/usr/local/lib/python3.4/dist-packages/django/core/handlers/base.py", line 132, in get_response
    response = wrapped_callback(request, *callback_args, **callback_kwargs)
  File "/usr/local/lib/python3.4/dist-packages/django/contrib/auth/decorators.py", line 22, in _wrapped_view
    return view_func(request, *args, **kwargs)
  File "/webapps/lis2/receivematerial/views.py", line 51, in tubes_get
    subgroup_lab = Subgroups.objects.get(pk=request.GET["subgroup"])
  File "/usr/local/lib/python3.4/dist-packages/django/db/models/manager.py", line 127, in manager_method
    return getattr(self.get_queryset(), name)(*args, **kwargs)
  File "/usr/local/lib/python3.4/dist-packages/django/db/models/query.py", line 325, in get
    clone = self.filter(*args, **kwargs)
  File "/usr/local/lib/python3.4/dist-packages/django/db/models/query.py", line 679, in filter
    return self._filter_or_exclude(False, *args, **kwargs)
  File "/usr/local/lib/python3.4/dist-packages/django/db/models/query.py", line 697, in _filter_or_exclude
    clone.query.add_q(Q(*args, **kwargs))
  File "/usr/local/lib/python3.4/dist-packages/django/db/models/sql/query.py", line 1309, in add_q
    clause, require_inner = self._add_q(where_part, self.used_aliases)
  File "/usr/local/lib/python3.4/dist-packages/django/db/models/sql/query.py", line 1337, in _add_q
    allow_joins=allow_joins, split_subq=split_subq,
  File "/usr/local/lib/python3.4/dist-packages/django/db/models/sql/query.py", line 1208, in build_filter
    condition = self.build_lookup(lookups, col, value)
  File "/usr/local/lib/python3.4/dist-packages/django/db/models/sql/query.py", line 1101, in build_lookup
    return final_lookup(lhs, rhs)
  File "/usr/local/lib/python3.4/dist-packages/django/db/models/lookups.py", line 101, in __init__
    self.rhs = self.get_prep_lookup()
  File "/usr/local/lib/python3.4/dist-packages/django/db/models/lookups.py", line 139, in get_prep_lookup
    return self.lhs.output_field.get_prep_lookup(self.lookup_name, self.rhs)
  File "/usr/local/lib/python3.4/dist-packages/django/db/models/fields/__init__.py", line 727, in get_prep_lookup
    return self.get_prep_value(value)
  File "/usr/local/lib/python3.4/dist-packages/django/db/models/fields/__init__.py", line 985, in get_prep_value
    return int(value)
ValueError: invalid literal for int() with base 10: 'undefined'
Not Found: /favicon.ico
Not Found: /directory/researches/sort
Internal Server Error: /directory/researches
Traceback (most recent call last):
  File "/usr/local/lib/python3.4/dist-packages/django/core/handlers/base.py", line 132, in get_response
    response = wrapped_callback(request, *callback_args, **callback_kwargs)
  File "/usr/local/lib/python3.4/dist-packages/django/views/decorators/csrf.py", line 58, in wrapped_view
    return view_func(*args, **kwargs)
  File "/usr/local/lib/python3.4/dist-packages/django/contrib/auth/decorators.py", line 22, in _wrapped_view
    return view_func(request, *args, **kwargs)
  File "/webapps/lis2/directory/views.py", line 89, in directory_researches
    return_result["researches"][research.sort_weight+"-"+i] = resdict
TypeError: unsupported operand type(s) for +: 'int' and 'str'
Internal Server Error: /directions/get/issledovaniya
Traceback (most recent call last):
  File "/usr/local/lib/python3.4/dist-packages/django/db/models/options.py", line 552, in get_field
    return self.fields_map[field_name]
KeyError: 'sort_weight'

During handling of the above exception, another exception occurred:

Traceback (most recent call last):
  File "/usr/local/lib/python3.4/dist-packages/django/db/models/sql/query.py", line 1367, in names_to_path
    field = opts.get_field(name)
  File "/usr/local/lib/python3.4/dist-packages/django/db/models/options.py", line 554, in get_field
    raise FieldDoesNotExist('%s has no field named %r' % (self.object_name, field_name))
django.core.exceptions.FieldDoesNotExist: Issledovaniya has no field named 'sort_weight'

During handling of the above exception, another exception occurred:

Traceback (most recent call last):
  File "/usr/local/lib/python3.4/dist-packages/django/core/handlers/base.py", line 132, in get_response
    response = wrapped_callback(request, *callback_args, **callback_kwargs)
  File "/usr/local/lib/python3.4/dist-packages/django/contrib/auth/decorators.py", line 22, in _wrapped_view
    return view_func(request, *args, **kwargs)
  File "/webapps/lis2/directions/views.py", line 718, in get_issledovaniya
    if len(iss) > 0:
  File "/usr/local/lib/python3.4/dist-packages/django/db/models/query.py", line 144, in __len__
    self._fetch_all()
  File "/usr/local/lib/python3.4/dist-packages/django/db/models/query.py", line 965, in _fetch_all
    self._result_cache = list(self.iterator())
  File "/usr/local/lib/python3.4/dist-packages/django/db/models/query.py", line 238, in iterator
    results = compiler.execute_sql()
  File "/usr/local/lib/python3.4/dist-packages/cachalot/monkey_patch.py", line 44, in inner
    out = original(compiler, *args, **kwargs)
  File "/usr/local/lib/python3.4/dist-packages/cachalot/monkey_patch.py", line 92, in inner
    cache_key = _get_query_cache_key(compiler)
  File "/usr/local/lib/python3.4/dist-packages/cachalot/utils.py", line 64, in _get_query_cache_key
    return import_string(cachalot_settings.CACHALOT_QUERY_KEYGEN)(compiler)
  File "/usr/local/lib/python3.4/dist-packages/cachalot/utils.py", line 41, in get_query_cache_key
    sql, params = compiler.as_sql()
  File "/usr/local/lib/python3.4/dist-packages/django/db/models/sql/compiler.py", line 378, in as_sql
    extra_select, order_by, group_by = self.pre_sql_setup()
  File "/usr/local/lib/python3.4/dist-packages/django/db/models/sql/compiler.py", line 49, in pre_sql_setup
    order_by = self.get_order_by()
  File "/usr/local/lib/python3.4/dist-packages/django/db/models/sql/compiler.py", line 286, in get_order_by
    field, self.query.get_meta(), default_order=asc))
  File "/usr/local/lib/python3.4/dist-packages/django/db/models/sql/compiler.py", line 558, in find_ordering_name
    field, targets, alias, joins, path, opts = self._setup_joins(pieces, opts, alias)
  File "/usr/local/lib/python3.4/dist-packages/django/db/models/sql/compiler.py", line 591, in _setup_joins
    pieces, opts, alias)
  File "/usr/local/lib/python3.4/dist-packages/django/db/models/sql/query.py", line 1471, in setup_joins
    names, opts, allow_many, fail_on_missing=True)
  File "/usr/local/lib/python3.4/dist-packages/django/db/models/sql/query.py", line 1396, in names_to_path
    "Choices are: %s" % (name, ", ".join(available)))
django.core.exceptions.FieldError: Cannot resolve keyword 'sort_weight' into field. Choices are: doc_confirmation, doc_confirmation_id, doc_save, doc_save_id, id, napravleniye, napravleniye_id, research, research_id, result, time_confirmation, time_save, tubes
Internal Server Error: /results/enter
Traceback (most recent call last):
  File "/usr/local/lib/python3.4/dist-packages/django/core/urlresolvers.py", line 394, in urlconf_module
    return self._urlconf_module
AttributeError: 'RegexURLResolver' object has no attribute '_urlconf_module'

During handling of the above exception, another exception occurred:

Traceback (most recent call last):
  File "/usr/local/lib/python3.4/dist-packages/django/core/handlers/base.py", line 108, in get_response
    response = middleware_method(request)
  File "/usr/local/lib/python3.4/dist-packages/django/middleware/common.py", line 74, in process_request
    if (not urlresolvers.is_valid_path(request.path_info, urlconf) and
  File "/usr/local/lib/python3.4/dist-packages/django/core/urlresolvers.py", line 647, in is_valid_path
    resolve(path, urlconf)
  File "/usr/local/lib/python3.4/dist-packages/django/core/urlresolvers.py", line 522, in resolve
    return get_resolver(urlconf).resolve(path)
  File "/usr/local/lib/python3.4/dist-packages/django/core/urlresolvers.py", line 366, in resolve
    for pattern in self.url_patterns:
  File "/usr/local/lib/python3.4/dist-packages/django/core/urlresolvers.py", line 402, in url_patterns
    patterns = getattr(self.urlconf_module, "urlpatterns", self.urlconf_module)
  File "/usr/local/lib/python3.4/dist-packages/django/core/urlresolvers.py", line 396, in urlconf_module
    self._urlconf_module = import_module(self.urlconf_name)
  File "/usr/lib/python3.4/importlib/__init__.py", line 109, in import_module
    return _bootstrap._gcd_import(name[level:], package, level)
  File "<frozen importlib._bootstrap>", line 2231, in _gcd_import
  File "<frozen importlib._bootstrap>", line 2214, in _find_and_load
  File "<frozen importlib._bootstrap>", line 2203, in _find_and_load_unlocked
  File "<frozen importlib._bootstrap>", line 1200, in _load_unlocked
  File "<frozen importlib._bootstrap>", line 1129, in _exec
  File "<frozen importlib._bootstrap>", line 1448, in exec_module
  File "<frozen importlib._bootstrap>", line 321, in _call_with_frames_removed
  File "/webapps/lis2/laboratory/urls.py", line 13, in <module>
    from results.views import enter, loadready, results_save, result_get, result_conformation, result_confirm, result_print, \
ImportError: cannot import name 'result_confirm_list'
Internal Server Error: /results/enter
Traceback (most recent call last):
  File "/usr/local/lib/python3.4/dist-packages/django/core/urlresolvers.py", line 394, in urlconf_module
    return self._urlconf_module
AttributeError: 'RegexURLResolver' object has no attribute '_urlconf_module'

During handling of the above exception, another exception occurred:

Traceback (most recent call last):
  File "/usr/local/lib/python3.4/dist-packages/django/core/handlers/base.py", line 108, in get_response
    response = middleware_method(request)
  File "/usr/local/lib/python3.4/dist-packages/django/middleware/common.py", line 74, in process_request
    if (not urlresolvers.is_valid_path(request.path_info, urlconf) and
  File "/usr/local/lib/python3.4/dist-packages/django/core/urlresolvers.py", line 647, in is_valid_path
    resolve(path, urlconf)
  File "/usr/local/lib/python3.4/dist-packages/django/core/urlresolvers.py", line 522, in resolve
    return get_resolver(urlconf).resolve(path)
  File "/usr/local/lib/python3.4/dist-packages/django/core/urlresolvers.py", line 366, in resolve
    for pattern in self.url_patterns:
  File "/usr/local/lib/python3.4/dist-packages/django/core/urlresolvers.py", line 402, in url_patterns
    patterns = getattr(self.urlconf_module, "urlpatterns", self.urlconf_module)
  File "/usr/local/lib/python3.4/dist-packages/django/core/urlresolvers.py", line 396, in urlconf_module
    self._urlconf_module = import_module(self.urlconf_name)
  File "/usr/lib/python3.4/importlib/__init__.py", line 109, in import_module
    return _bootstrap._gcd_import(name[level:], package, level)
  File "<frozen importlib._bootstrap>", line 2231, in _gcd_import
  File "<frozen importlib._bootstrap>", line 2214, in _find_and_load
  File "<frozen importlib._bootstrap>", line 2203, in _find_and_load_unlocked
  File "<frozen importlib._bootstrap>", line 1200, in _load_unlocked
  File "<frozen importlib._bootstrap>", line 1129, in _exec
  File "<frozen importlib._bootstrap>", line 1448, in exec_module
  File "<frozen importlib._bootstrap>", line 321, in _call_with_frames_removed
  File "/webapps/lis2/laboratory/urls.py", line 13, in <module>
    from results.views import enter, loadready, results_save, result_get, result_conformation, result_confirm, result_print, \
ImportError: cannot import name 'result_confirm_list'
Not Found: /results/confirm/list
Internal Server Error: /results/confirm/list
Traceback (most recent call last):
  File "/usr/local/lib/python3.4/dist-packages/django/utils/datastructures.py", line 320, in __getitem__
    list_ = super(MultiValueDict, self).__getitem__(key)
KeyError: 'pk'

During handling of the above exception, another exception occurred:

Traceback (most recent call last):
  File "/usr/local/lib/python3.4/dist-packages/django/core/handlers/base.py", line 132, in get_response
    response = wrapped_callback(request, *callback_args, **callback_kwargs)
  File "/usr/local/lib/python3.4/dist-packages/django/views/decorators/csrf.py", line 58, in wrapped_view
    return view_func(*args, **kwargs)
  File "/usr/local/lib/python3.4/dist-packages/django/contrib/auth/decorators.py", line 22, in _wrapped_view
    return view_func(request, *args, **kwargs)
  File "/webapps/lis2/results/views.py", line 130, in result_confirm_list
    slog.Log(key=request.POST["pk"], type=14, body="", user=request.user.doctorprofile).save()
  File "/usr/local/lib/python3.4/dist-packages/django/utils/datastructures.py", line 322, in __getitem__
    raise MultiValueDictKeyError(repr(key))
django.utils.datastructures.MultiValueDictKeyError: "'pk'"
Not Found: /dashboard/from
Internal Server Error: /tubes/get
Traceback (most recent call last):
  File "/usr/local/lib/python3.4/dist-packages/django/core/handlers/base.py", line 132, in get_response
    response = wrapped_callback(request, *callback_args, **callback_kwargs)
  File "/usr/local/lib/python3.4/dist-packages/django/contrib/auth/decorators.py", line 22, in _wrapped_view
    return view_func(request, *args, **kwargs)
  File "/webapps/lis2/receivematerial/views.py", line 52, in tubes_get
    podrazledeniye = Podrazdeleniya.objects.get(pk=request.GET["from"])
  File "/usr/local/lib/python3.4/dist-packages/django/db/models/manager.py", line 127, in manager_method
    return getattr(self.get_queryset(), name)(*args, **kwargs)
  File "/usr/local/lib/python3.4/dist-packages/django/db/models/query.py", line 325, in get
    clone = self.filter(*args, **kwargs)
  File "/usr/local/lib/python3.4/dist-packages/django/db/models/query.py", line 679, in filter
    return self._filter_or_exclude(False, *args, **kwargs)
  File "/usr/local/lib/python3.4/dist-packages/django/db/models/query.py", line 697, in _filter_or_exclude
    clone.query.add_q(Q(*args, **kwargs))
  File "/usr/local/lib/python3.4/dist-packages/django/db/models/sql/query.py", line 1309, in add_q
    clause, require_inner = self._add_q(where_part, self.used_aliases)
  File "/usr/local/lib/python3.4/dist-packages/django/db/models/sql/query.py", line 1337, in _add_q
    allow_joins=allow_joins, split_subq=split_subq,
  File "/usr/local/lib/python3.4/dist-packages/django/db/models/sql/query.py", line 1208, in build_filter
    condition = self.build_lookup(lookups, col, value)
  File "/usr/local/lib/python3.4/dist-packages/django/db/models/sql/query.py", line 1101, in build_lookup
    return final_lookup(lhs, rhs)
  File "/usr/local/lib/python3.4/dist-packages/django/db/models/lookups.py", line 101, in __init__
    self.rhs = self.get_prep_lookup()
  File "/usr/local/lib/python3.4/dist-packages/django/db/models/lookups.py", line 139, in get_prep_lookup
    return self.lhs.output_field.get_prep_lookup(self.lookup_name, self.rhs)
  File "/usr/local/lib/python3.4/dist-packages/django/db/models/fields/__init__.py", line 727, in get_prep_lookup
    return self.get_prep_value(value)
  File "/usr/local/lib/python3.4/dist-packages/django/db/models/fields/__init__.py", line 985, in get_prep_value
    return int(value)
ValueError: invalid literal for int() with base 10: 'undefined'
Not Found: /dashboard/from
Internal Server Error: /tubes/get
Traceback (most recent call last):
  File "/usr/local/lib/python3.4/dist-packages/django/core/handlers/base.py", line 132, in get_response
    response = wrapped_callback(request, *callback_args, **callback_kwargs)
  File "/usr/local/lib/python3.4/dist-packages/django/contrib/auth/decorators.py", line 22, in _wrapped_view
    return view_func(request, *args, **kwargs)
  File "/webapps/lis2/receivematerial/views.py", line 52, in tubes_get
    podrazledeniye = Podrazdeleniya.objects.get(pk=request.GET["from"])
  File "/usr/local/lib/python3.4/dist-packages/django/db/models/manager.py", line 127, in manager_method
    return getattr(self.get_queryset(), name)(*args, **kwargs)
  File "/usr/local/lib/python3.4/dist-packages/django/db/models/query.py", line 325, in get
    clone = self.filter(*args, **kwargs)
  File "/usr/local/lib/python3.4/dist-packages/django/db/models/query.py", line 679, in filter
    return self._filter_or_exclude(False, *args, **kwargs)
  File "/usr/local/lib/python3.4/dist-packages/django/db/models/query.py", line 697, in _filter_or_exclude
    clone.query.add_q(Q(*args, **kwargs))
  File "/usr/local/lib/python3.4/dist-packages/django/db/models/sql/query.py", line 1309, in add_q
    clause, require_inner = self._add_q(where_part, self.used_aliases)
  File "/usr/local/lib/python3.4/dist-packages/django/db/models/sql/query.py", line 1337, in _add_q
    allow_joins=allow_joins, split_subq=split_subq,
  File "/usr/local/lib/python3.4/dist-packages/django/db/models/sql/query.py", line 1208, in build_filter
    condition = self.build_lookup(lookups, col, value)
  File "/usr/local/lib/python3.4/dist-packages/django/db/models/sql/query.py", line 1101, in build_lookup
    return final_lookup(lhs, rhs)
  File "/usr/local/lib/python3.4/dist-packages/django/db/models/lookups.py", line 101, in __init__
    self.rhs = self.get_prep_lookup()
  File "/usr/local/lib/python3.4/dist-packages/django/db/models/lookups.py", line 139, in get_prep_lookup
    return self.lhs.output_field.get_prep_lookup(self.lookup_name, self.rhs)
  File "/usr/local/lib/python3.4/dist-packages/django/db/models/fields/__init__.py", line 727, in get_prep_lookup
    return self.get_prep_value(value)
  File "/usr/local/lib/python3.4/dist-packages/django/db/models/fields/__init__.py", line 985, in get_prep_value
    return int(value)
ValueError: invalid literal for int() with base 10: 'undefined'
Not Found: /dashboard/from
Internal Server Error: /tubes/get
Traceback (most recent call last):
  File "/usr/local/lib/python3.4/dist-packages/django/core/handlers/base.py", line 132, in get_response
    response = wrapped_callback(request, *callback_args, **callback_kwargs)
  File "/usr/local/lib/python3.4/dist-packages/django/contrib/auth/decorators.py", line 22, in _wrapped_view
    return view_func(request, *args, **kwargs)
  File "/webapps/lis2/receivematerial/views.py", line 52, in tubes_get
    podrazledeniye = Podrazdeleniya.objects.get(pk=request.GET["from"])
  File "/usr/local/lib/python3.4/dist-packages/django/db/models/manager.py", line 127, in manager_method
    return getattr(self.get_queryset(), name)(*args, **kwargs)
  File "/usr/local/lib/python3.4/dist-packages/django/db/models/query.py", line 325, in get
    clone = self.filter(*args, **kwargs)
  File "/usr/local/lib/python3.4/dist-packages/django/db/models/query.py", line 679, in filter
    return self._filter_or_exclude(False, *args, **kwargs)
  File "/usr/local/lib/python3.4/dist-packages/django/db/models/query.py", line 697, in _filter_or_exclude
    clone.query.add_q(Q(*args, **kwargs))
  File "/usr/local/lib/python3.4/dist-packages/django/db/models/sql/query.py", line 1309, in add_q
    clause, require_inner = self._add_q(where_part, self.used_aliases)
  File "/usr/local/lib/python3.4/dist-packages/django/db/models/sql/query.py", line 1337, in _add_q
    allow_joins=allow_joins, split_subq=split_subq,
  File "/usr/local/lib/python3.4/dist-packages/django/db/models/sql/query.py", line 1208, in build_filter
    condition = self.build_lookup(lookups, col, value)
  File "/usr/local/lib/python3.4/dist-packages/django/db/models/sql/query.py", line 1101, in build_lookup
    return final_lookup(lhs, rhs)
  File "/usr/local/lib/python3.4/dist-packages/django/db/models/lookups.py", line 101, in __init__
    self.rhs = self.get_prep_lookup()
  File "/usr/local/lib/python3.4/dist-packages/django/db/models/lookups.py", line 139, in get_prep_lookup
    return self.lhs.output_field.get_prep_lookup(self.lookup_name, self.rhs)
  File "/usr/local/lib/python3.4/dist-packages/django/db/models/fields/__init__.py", line 727, in get_prep_lookup
    return self.get_prep_value(value)
  File "/usr/local/lib/python3.4/dist-packages/django/db/models/fields/__init__.py", line 985, in get_prep_value
    return int(value)
ValueError: invalid literal for int() with base 10: 'undefined'
Not Found: /dashboard/from
Internal Server Error: /tubes/get
Traceback (most recent call last):
  File "/usr/local/lib/python3.4/dist-packages/django/core/handlers/base.py", line 132, in get_response
    response = wrapped_callback(request, *callback_args, **callback_kwargs)
  File "/usr/local/lib/python3.4/dist-packages/django/contrib/auth/decorators.py", line 22, in _wrapped_view
    return view_func(request, *args, **kwargs)
  File "/webapps/lis2/receivematerial/views.py", line 52, in tubes_get
    podrazledeniye = Podrazdeleniya.objects.get(pk=request.GET["from"])
  File "/usr/local/lib/python3.4/dist-packages/django/db/models/manager.py", line 127, in manager_method
    return getattr(self.get_queryset(), name)(*args, **kwargs)
  File "/usr/local/lib/python3.4/dist-packages/django/db/models/query.py", line 325, in get
    clone = self.filter(*args, **kwargs)
  File "/usr/local/lib/python3.4/dist-packages/django/db/models/query.py", line 679, in filter
    return self._filter_or_exclude(False, *args, **kwargs)
  File "/usr/local/lib/python3.4/dist-packages/django/db/models/query.py", line 697, in _filter_or_exclude
    clone.query.add_q(Q(*args, **kwargs))
  File "/usr/local/lib/python3.4/dist-packages/django/db/models/sql/query.py", line 1309, in add_q
    clause, require_inner = self._add_q(where_part, self.used_aliases)
  File "/usr/local/lib/python3.4/dist-packages/django/db/models/sql/query.py", line 1337, in _add_q
    allow_joins=allow_joins, split_subq=split_subq,
  File "/usr/local/lib/python3.4/dist-packages/django/db/models/sql/query.py", line 1208, in build_filter
    condition = self.build_lookup(lookups, col, value)
  File "/usr/local/lib/python3.4/dist-packages/django/db/models/sql/query.py", line 1101, in build_lookup
    return final_lookup(lhs, rhs)
  File "/usr/local/lib/python3.4/dist-packages/django/db/models/lookups.py", line 101, in __init__
    self.rhs = self.get_prep_lookup()
  File "/usr/local/lib/python3.4/dist-packages/django/db/models/lookups.py", line 139, in get_prep_lookup
    return self.lhs.output_field.get_prep_lookup(self.lookup_name, self.rhs)
  File "/usr/local/lib/python3.4/dist-packages/django/db/models/fields/__init__.py", line 727, in get_prep_lookup
    return self.get_prep_value(value)
  File "/usr/local/lib/python3.4/dist-packages/django/db/models/fields/__init__.py", line 985, in get_prep_value
    return int(value)
ValueError: invalid literal for int() with base 10: 'undefined'
Internal Server Error: /tubes/get
Traceback (most recent call last):
  File "/usr/local/lib/python3.4/dist-packages/django/core/handlers/base.py", line 132, in get_response
    response = wrapped_callback(request, *callback_args, **callback_kwargs)
  File "/usr/local/lib/python3.4/dist-packages/django/contrib/auth/decorators.py", line 22, in _wrapped_view
    return view_func(request, *args, **kwargs)
  File "/webapps/lis2/receivematerial/views.py", line 52, in tubes_get
    podrazledeniye = Podrazdeleniya.objects.get(pk=request.GET["from"])
  File "/usr/local/lib/python3.4/dist-packages/django/db/models/manager.py", line 127, in manager_method
    return getattr(self.get_queryset(), name)(*args, **kwargs)
  File "/usr/local/lib/python3.4/dist-packages/django/db/models/query.py", line 325, in get
    clone = self.filter(*args, **kwargs)
  File "/usr/local/lib/python3.4/dist-packages/django/db/models/query.py", line 679, in filter
    return self._filter_or_exclude(False, *args, **kwargs)
  File "/usr/local/lib/python3.4/dist-packages/django/db/models/query.py", line 697, in _filter_or_exclude
    clone.query.add_q(Q(*args, **kwargs))
  File "/usr/local/lib/python3.4/dist-packages/django/db/models/sql/query.py", line 1309, in add_q
    clause, require_inner = self._add_q(where_part, self.used_aliases)
  File "/usr/local/lib/python3.4/dist-packages/django/db/models/sql/query.py", line 1337, in _add_q
    allow_joins=allow_joins, split_subq=split_subq,
  File "/usr/local/lib/python3.4/dist-packages/django/db/models/sql/query.py", line 1208, in build_filter
    condition = self.build_lookup(lookups, col, value)
  File "/usr/local/lib/python3.4/dist-packages/django/db/models/sql/query.py", line 1101, in build_lookup
    return final_lookup(lhs, rhs)
  File "/usr/local/lib/python3.4/dist-packages/django/db/models/lookups.py", line 101, in __init__
    self.rhs = self.get_prep_lookup()
  File "/usr/local/lib/python3.4/dist-packages/django/db/models/lookups.py", line 139, in get_prep_lookup
    return self.lhs.output_field.get_prep_lookup(self.lookup_name, self.rhs)
  File "/usr/local/lib/python3.4/dist-packages/django/db/models/fields/__init__.py", line 727, in get_prep_lookup
    return self.get_prep_value(value)
  File "/usr/local/lib/python3.4/dist-packages/django/db/models/fields/__init__.py", line 985, in get_prep_value
    return int(value)
ValueError: invalid literal for int() with base 10: 'undefined'
Internal Server Error: /tubes/get
Traceback (most recent call last):
  File "/usr/local/lib/python3.4/dist-packages/django/core/handlers/base.py", line 132, in get_response
    response = wrapped_callback(request, *callback_args, **callback_kwargs)
  File "/usr/local/lib/python3.4/dist-packages/django/contrib/auth/decorators.py", line 22, in _wrapped_view
    return view_func(request, *args, **kwargs)
  File "/webapps/lis2/receivematerial/views.py", line 52, in tubes_get
    podrazledeniye = Podrazdeleniya.objects.get(pk=request.GET["from"])
  File "/usr/local/lib/python3.4/dist-packages/django/db/models/manager.py", line 127, in manager_method
    return getattr(self.get_queryset(), name)(*args, **kwargs)
  File "/usr/local/lib/python3.4/dist-packages/django/db/models/query.py", line 325, in get
    clone = self.filter(*args, **kwargs)
  File "/usr/local/lib/python3.4/dist-packages/django/db/models/query.py", line 679, in filter
    return self._filter_or_exclude(False, *args, **kwargs)
  File "/usr/local/lib/python3.4/dist-packages/django/db/models/query.py", line 697, in _filter_or_exclude
    clone.query.add_q(Q(*args, **kwargs))
  File "/usr/local/lib/python3.4/dist-packages/django/db/models/sql/query.py", line 1309, in add_q
    clause, require_inner = self._add_q(where_part, self.used_aliases)
  File "/usr/local/lib/python3.4/dist-packages/django/db/models/sql/query.py", line 1337, in _add_q
    allow_joins=allow_joins, split_subq=split_subq,
  File "/usr/local/lib/python3.4/dist-packages/django/db/models/sql/query.py", line 1208, in build_filter
    condition = self.build_lookup(lookups, col, value)
  File "/usr/local/lib/python3.4/dist-packages/django/db/models/sql/query.py", line 1101, in build_lookup
    return final_lookup(lhs, rhs)
  File "/usr/local/lib/python3.4/dist-packages/django/db/models/lookups.py", line 101, in __init__
    self.rhs = self.get_prep_lookup()
  File "/usr/local/lib/python3.4/dist-packages/django/db/models/lookups.py", line 139, in get_prep_lookup
    return self.lhs.output_field.get_prep_lookup(self.lookup_name, self.rhs)
  File "/usr/local/lib/python3.4/dist-packages/django/db/models/fields/__init__.py", line 727, in get_prep_lookup
    return self.get_prep_value(value)
  File "/usr/local/lib/python3.4/dist-packages/django/db/models/fields/__init__.py", line 985, in get_prep_value
    return int(value)
ValueError: invalid literal for int() with base 10: 'undefined'
Internal Server Error: /tubes/get
Traceback (most recent call last):
  File "/usr/local/lib/python3.4/dist-packages/django/core/handlers/base.py", line 132, in get_response
    response = wrapped_callback(request, *callback_args, **callback_kwargs)
  File "/usr/local/lib/python3.4/dist-packages/django/contrib/auth/decorators.py", line 22, in _wrapped_view
    return view_func(request, *args, **kwargs)
  File "/webapps/lis2/receivematerial/views.py", line 52, in tubes_get
    podrazledeniye = Podrazdeleniya.objects.get(pk=request.GET["from"])
  File "/usr/local/lib/python3.4/dist-packages/django/db/models/manager.py", line 127, in manager_method
    return getattr(self.get_queryset(), name)(*args, **kwargs)
  File "/usr/local/lib/python3.4/dist-packages/django/db/models/query.py", line 325, in get
    clone = self.filter(*args, **kwargs)
  File "/usr/local/lib/python3.4/dist-packages/django/db/models/query.py", line 679, in filter
    return self._filter_or_exclude(False, *args, **kwargs)
  File "/usr/local/lib/python3.4/dist-packages/django/db/models/query.py", line 697, in _filter_or_exclude
    clone.query.add_q(Q(*args, **kwargs))
  File "/usr/local/lib/python3.4/dist-packages/django/db/models/sql/query.py", line 1309, in add_q
    clause, require_inner = self._add_q(where_part, self.used_aliases)
  File "/usr/local/lib/python3.4/dist-packages/django/db/models/sql/query.py", line 1337, in _add_q
    allow_joins=allow_joins, split_subq=split_subq,
  File "/usr/local/lib/python3.4/dist-packages/django/db/models/sql/query.py", line 1208, in build_filter
    condition = self.build_lookup(lookups, col, value)
  File "/usr/local/lib/python3.4/dist-packages/django/db/models/sql/query.py", line 1101, in build_lookup
    return final_lookup(lhs, rhs)
  File "/usr/local/lib/python3.4/dist-packages/django/db/models/lookups.py", line 101, in __init__
    self.rhs = self.get_prep_lookup()
  File "/usr/local/lib/python3.4/dist-packages/django/db/models/lookups.py", line 139, in get_prep_lookup
    return self.lhs.output_field.get_prep_lookup(self.lookup_name, self.rhs)
  File "/usr/local/lib/python3.4/dist-packages/django/db/models/fields/__init__.py", line 727, in get_prep_lookup
    return self.get_prep_value(value)
  File "/usr/local/lib/python3.4/dist-packages/django/db/models/fields/__init__.py", line 985, in get_prep_value
    return int(value)
ValueError: invalid literal for int() with base 10: 'undefined'
Internal Server Error: /tubes/get
Traceback (most recent call last):
  File "/usr/local/lib/python3.4/dist-packages/django/core/handlers/base.py", line 132, in get_response
    response = wrapped_callback(request, *callback_args, **callback_kwargs)
  File "/usr/local/lib/python3.4/dist-packages/django/contrib/auth/decorators.py", line 22, in _wrapped_view
    return view_func(request, *args, **kwargs)
  File "/webapps/lis2/receivematerial/views.py", line 52, in tubes_get
    podrazledeniye = Podrazdeleniya.objects.get(pk=request.GET["from"])
  File "/usr/local/lib/python3.4/dist-packages/django/db/models/manager.py", line 127, in manager_method
    return getattr(self.get_queryset(), name)(*args, **kwargs)
  File "/usr/local/lib/python3.4/dist-packages/django/db/models/query.py", line 325, in get
    clone = self.filter(*args, **kwargs)
  File "/usr/local/lib/python3.4/dist-packages/django/db/models/query.py", line 679, in filter
    return self._filter_or_exclude(False, *args, **kwargs)
  File "/usr/local/lib/python3.4/dist-packages/django/db/models/query.py", line 697, in _filter_or_exclude
    clone.query.add_q(Q(*args, **kwargs))
  File "/usr/local/lib/python3.4/dist-packages/django/db/models/sql/query.py", line 1309, in add_q
    clause, require_inner = self._add_q(where_part, self.used_aliases)
  File "/usr/local/lib/python3.4/dist-packages/django/db/models/sql/query.py", line 1337, in _add_q
    allow_joins=allow_joins, split_subq=split_subq,
  File "/usr/local/lib/python3.4/dist-packages/django/db/models/sql/query.py", line 1208, in build_filter
    condition = self.build_lookup(lookups, col, value)
  File "/usr/local/lib/python3.4/dist-packages/django/db/models/sql/query.py", line 1101, in build_lookup
    return final_lookup(lhs, rhs)
  File "/usr/local/lib/python3.4/dist-packages/django/db/models/lookups.py", line 101, in __init__
    self.rhs = self.get_prep_lookup()
  File "/usr/local/lib/python3.4/dist-packages/django/db/models/lookups.py", line 139, in get_prep_lookup
    return self.lhs.output_field.get_prep_lookup(self.lookup_name, self.rhs)
  File "/usr/local/lib/python3.4/dist-packages/django/db/models/fields/__init__.py", line 727, in get_prep_lookup
    return self.get_prep_value(value)
  File "/usr/local/lib/python3.4/dist-packages/django/db/models/fields/__init__.py", line 985, in get_prep_value
    return int(value)
ValueError: invalid literal for int() with base 10: 'undefined'
Internal Server Error: /dashboard/from
Traceback (most recent call last):
  File "/usr/local/lib/python3.4/dist-packages/django/core/handlers/base.py", line 132, in get_response
    response = wrapped_callback(request, *callback_args, **callback_kwargs)
  File "/usr/local/lib/python3.4/dist-packages/django/contrib/auth/decorators.py", line 22, in _wrapped_view
    return view_func(request, *args, **kwargs)
  File "/webapps/lis2/dashboard/views.py", line 181, in dashboard_from
    result[podr.pk] = {"pk": podr.pk, "title": podr.title, "tubes": TubesRegistration.objects.filter(doc_get__podrazileniye=podr, doc_recive__isNull=True).count()}
  File "/usr/local/lib/python3.4/dist-packages/django/db/models/manager.py", line 127, in manager_method
    return getattr(self.get_queryset(), name)(*args, **kwargs)
  File "/usr/local/lib/python3.4/dist-packages/django/db/models/query.py", line 679, in filter
    return self._filter_or_exclude(False, *args, **kwargs)
  File "/usr/local/lib/python3.4/dist-packages/django/db/models/query.py", line 697, in _filter_or_exclude
    clone.query.add_q(Q(*args, **kwargs))
  File "/usr/local/lib/python3.4/dist-packages/django/db/models/sql/query.py", line 1309, in add_q
    clause, require_inner = self._add_q(where_part, self.used_aliases)
  File "/usr/local/lib/python3.4/dist-packages/django/db/models/sql/query.py", line 1337, in _add_q
    allow_joins=allow_joins, split_subq=split_subq,
  File "/usr/local/lib/python3.4/dist-packages/django/db/models/sql/query.py", line 1199, in build_filter
    lookups, value)
  File "/usr/local/lib/python3.4/dist-packages/django/db/models/fields/related.py", line 1772, in get_lookup_constraint
    raise TypeError('Related Field got invalid lookup: %s' % lookup_type)
TypeError: Related Field got invalid lookup: isNull
Internal Server Error: /tubes/get
Traceback (most recent call last):
  File "/usr/local/lib/python3.4/dist-packages/django/core/handlers/base.py", line 132, in get_response
    response = wrapped_callback(request, *callback_args, **callback_kwargs)
  File "/usr/local/lib/python3.4/dist-packages/django/contrib/auth/decorators.py", line 22, in _wrapped_view
    return view_func(request, *args, **kwargs)
  File "/webapps/lis2/receivematerial/views.py", line 52, in tubes_get
    podrazledeniye = Podrazdeleniya.objects.get(pk=request.GET["from"])
  File "/usr/local/lib/python3.4/dist-packages/django/db/models/manager.py", line 127, in manager_method
    return getattr(self.get_queryset(), name)(*args, **kwargs)
  File "/usr/local/lib/python3.4/dist-packages/django/db/models/query.py", line 325, in get
    clone = self.filter(*args, **kwargs)
  File "/usr/local/lib/python3.4/dist-packages/django/db/models/query.py", line 679, in filter
    return self._filter_or_exclude(False, *args, **kwargs)
  File "/usr/local/lib/python3.4/dist-packages/django/db/models/query.py", line 697, in _filter_or_exclude
    clone.query.add_q(Q(*args, **kwargs))
  File "/usr/local/lib/python3.4/dist-packages/django/db/models/sql/query.py", line 1309, in add_q
    clause, require_inner = self._add_q(where_part, self.used_aliases)
  File "/usr/local/lib/python3.4/dist-packages/django/db/models/sql/query.py", line 1337, in _add_q
    allow_joins=allow_joins, split_subq=split_subq,
  File "/usr/local/lib/python3.4/dist-packages/django/db/models/sql/query.py", line 1208, in build_filter
    condition = self.build_lookup(lookups, col, value)
  File "/usr/local/lib/python3.4/dist-packages/django/db/models/sql/query.py", line 1101, in build_lookup
    return final_lookup(lhs, rhs)
  File "/usr/local/lib/python3.4/dist-packages/django/db/models/lookups.py", line 101, in __init__
    self.rhs = self.get_prep_lookup()
  File "/usr/local/lib/python3.4/dist-packages/django/db/models/lookups.py", line 139, in get_prep_lookup
    return self.lhs.output_field.get_prep_lookup(self.lookup_name, self.rhs)
  File "/usr/local/lib/python3.4/dist-packages/django/db/models/fields/__init__.py", line 727, in get_prep_lookup
    return self.get_prep_value(value)
  File "/usr/local/lib/python3.4/dist-packages/django/db/models/fields/__init__.py", line 985, in get_prep_value
    return int(value)
ValueError: invalid literal for int() with base 10: 'undefined'
Internal Server Error: /tubes/get
Traceback (most recent call last):
  File "/usr/local/lib/python3.4/dist-packages/django/core/handlers/base.py", line 132, in get_response
    response = wrapped_callback(request, *callback_args, **callback_kwargs)
  File "/usr/local/lib/python3.4/dist-packages/django/contrib/auth/decorators.py", line 22, in _wrapped_view
    return view_func(request, *args, **kwargs)
  File "/webapps/lis2/receivematerial/views.py", line 52, in tubes_get
    podrazledeniye = Podrazdeleniya.objects.get(pk=request.GET["from"])
  File "/usr/local/lib/python3.4/dist-packages/django/db/models/manager.py", line 127, in manager_method
    return getattr(self.get_queryset(), name)(*args, **kwargs)
  File "/usr/local/lib/python3.4/dist-packages/django/db/models/query.py", line 325, in get
    clone = self.filter(*args, **kwargs)
  File "/usr/local/lib/python3.4/dist-packages/django/db/models/query.py", line 679, in filter
    return self._filter_or_exclude(False, *args, **kwargs)
  File "/usr/local/lib/python3.4/dist-packages/django/db/models/query.py", line 697, in _filter_or_exclude
    clone.query.add_q(Q(*args, **kwargs))
  File "/usr/local/lib/python3.4/dist-packages/django/db/models/sql/query.py", line 1309, in add_q
    clause, require_inner = self._add_q(where_part, self.used_aliases)
  File "/usr/local/lib/python3.4/dist-packages/django/db/models/sql/query.py", line 1337, in _add_q
    allow_joins=allow_joins, split_subq=split_subq,
  File "/usr/local/lib/python3.4/dist-packages/django/db/models/sql/query.py", line 1208, in build_filter
    condition = self.build_lookup(lookups, col, value)
  File "/usr/local/lib/python3.4/dist-packages/django/db/models/sql/query.py", line 1101, in build_lookup
    return final_lookup(lhs, rhs)
  File "/usr/local/lib/python3.4/dist-packages/django/db/models/lookups.py", line 101, in __init__
    self.rhs = self.get_prep_lookup()
  File "/usr/local/lib/python3.4/dist-packages/django/db/models/lookups.py", line 139, in get_prep_lookup
    return self.lhs.output_field.get_prep_lookup(self.lookup_name, self.rhs)
  File "/usr/local/lib/python3.4/dist-packages/django/db/models/fields/__init__.py", line 727, in get_prep_lookup
    return self.get_prep_value(value)
  File "/usr/local/lib/python3.4/dist-packages/django/db/models/fields/__init__.py", line 985, in get_prep_value
    return int(value)
ValueError: invalid literal for int() with base 10: 'undefined'
Internal Server Error: /tubes/get
Traceback (most recent call last):
  File "/usr/local/lib/python3.4/dist-packages/django/core/handlers/base.py", line 132, in get_response
    response = wrapped_callback(request, *callback_args, **callback_kwargs)
  File "/usr/local/lib/python3.4/dist-packages/django/contrib/auth/decorators.py", line 22, in _wrapped_view
    return view_func(request, *args, **kwargs)
  File "/webapps/lis2/receivematerial/views.py", line 52, in tubes_get
    podrazledeniye = Podrazdeleniya.objects.get(pk=request.GET["from"])
  File "/usr/local/lib/python3.4/dist-packages/django/db/models/manager.py", line 127, in manager_method
    return getattr(self.get_queryset(), name)(*args, **kwargs)
  File "/usr/local/lib/python3.4/dist-packages/django/db/models/query.py", line 325, in get
    clone = self.filter(*args, **kwargs)
  File "/usr/local/lib/python3.4/dist-packages/django/db/models/query.py", line 679, in filter
    return self._filter_or_exclude(False, *args, **kwargs)
  File "/usr/local/lib/python3.4/dist-packages/django/db/models/query.py", line 697, in _filter_or_exclude
    clone.query.add_q(Q(*args, **kwargs))
  File "/usr/local/lib/python3.4/dist-packages/django/db/models/sql/query.py", line 1309, in add_q
    clause, require_inner = self._add_q(where_part, self.used_aliases)
  File "/usr/local/lib/python3.4/dist-packages/django/db/models/sql/query.py", line 1337, in _add_q
    allow_joins=allow_joins, split_subq=split_subq,
  File "/usr/local/lib/python3.4/dist-packages/django/db/models/sql/query.py", line 1208, in build_filter
    condition = self.build_lookup(lookups, col, value)
  File "/usr/local/lib/python3.4/dist-packages/django/db/models/sql/query.py", line 1101, in build_lookup
    return final_lookup(lhs, rhs)
  File "/usr/local/lib/python3.4/dist-packages/django/db/models/lookups.py", line 101, in __init__
    self.rhs = self.get_prep_lookup()
  File "/usr/local/lib/python3.4/dist-packages/django/db/models/lookups.py", line 139, in get_prep_lookup
    return self.lhs.output_field.get_prep_lookup(self.lookup_name, self.rhs)
  File "/usr/local/lib/python3.4/dist-packages/django/db/models/fields/__init__.py", line 727, in get_prep_lookup
    return self.get_prep_value(value)
  File "/usr/local/lib/python3.4/dist-packages/django/db/models/fields/__init__.py", line 985, in get_prep_value
    return int(value)
ValueError: invalid literal for int() with base 10: 'undefined'
Internal Server Error: /dashboard/from
Traceback (most recent call last):
  File "/usr/local/lib/python3.4/dist-packages/django/utils/datastructures.py", line 320, in __getitem__
    list_ = super(MultiValueDict, self).__getitem__(key)
KeyError: 'subgroup'

During handling of the above exception, another exception occurred:

Traceback (most recent call last):
  File "/usr/local/lib/python3.4/dist-packages/django/core/handlers/base.py", line 132, in get_response
    response = wrapped_callback(request, *callback_args, **callback_kwargs)
  File "/usr/local/lib/python3.4/dist-packages/django/contrib/auth/decorators.py", line 22, in _wrapped_view
    return view_func(request, *args, **kwargs)
  File "/webapps/lis2/dashboard/views.py", line 179, in dashboard_from
    subgroup_lab = Subgroups.objects.get(pk=request.GET["subgroup"])
  File "/usr/local/lib/python3.4/dist-packages/django/utils/datastructures.py", line 322, in __getitem__
    raise MultiValueDictKeyError(repr(key))
django.utils.datastructures.MultiValueDictKeyError: "'subgroup'"
Internal Server Error: /tubes/get
Traceback (most recent call last):
  File "/usr/local/lib/python3.4/dist-packages/django/core/handlers/base.py", line 132, in get_response
    response = wrapped_callback(request, *callback_args, **callback_kwargs)
  File "/usr/local/lib/python3.4/dist-packages/django/contrib/auth/decorators.py", line 22, in _wrapped_view
    return view_func(request, *args, **kwargs)
  File "/webapps/lis2/receivematerial/views.py", line 52, in tubes_get
    podrazledeniye = Podrazdeleniya.objects.get(pk=request.GET["from"])
  File "/usr/local/lib/python3.4/dist-packages/django/db/models/manager.py", line 127, in manager_method
    return getattr(self.get_queryset(), name)(*args, **kwargs)
  File "/usr/local/lib/python3.4/dist-packages/django/db/models/query.py", line 325, in get
    clone = self.filter(*args, **kwargs)
  File "/usr/local/lib/python3.4/dist-packages/django/db/models/query.py", line 679, in filter
    return self._filter_or_exclude(False, *args, **kwargs)
  File "/usr/local/lib/python3.4/dist-packages/django/db/models/query.py", line 697, in _filter_or_exclude
    clone.query.add_q(Q(*args, **kwargs))
  File "/usr/local/lib/python3.4/dist-packages/django/db/models/sql/query.py", line 1309, in add_q
    clause, require_inner = self._add_q(where_part, self.used_aliases)
  File "/usr/local/lib/python3.4/dist-packages/django/db/models/sql/query.py", line 1337, in _add_q
    allow_joins=allow_joins, split_subq=split_subq,
  File "/usr/local/lib/python3.4/dist-packages/django/db/models/sql/query.py", line 1208, in build_filter
    condition = self.build_lookup(lookups, col, value)
  File "/usr/local/lib/python3.4/dist-packages/django/db/models/sql/query.py", line 1101, in build_lookup
    return final_lookup(lhs, rhs)
  File "/usr/local/lib/python3.4/dist-packages/django/db/models/lookups.py", line 101, in __init__
    self.rhs = self.get_prep_lookup()
  File "/usr/local/lib/python3.4/dist-packages/django/db/models/lookups.py", line 139, in get_prep_lookup
    return self.lhs.output_field.get_prep_lookup(self.lookup_name, self.rhs)
  File "/usr/local/lib/python3.4/dist-packages/django/db/models/fields/__init__.py", line 727, in get_prep_lookup
    return self.get_prep_value(value)
  File "/usr/local/lib/python3.4/dist-packages/django/db/models/fields/__init__.py", line 985, in get_prep_value
    return int(value)
ValueError: invalid literal for int() with base 10: 'undefined'
Internal Server Error: /tubes/get
Traceback (most recent call last):
  File "/usr/local/lib/python3.4/dist-packages/django/core/handlers/base.py", line 132, in get_response
    response = wrapped_callback(request, *callback_args, **callback_kwargs)
  File "/usr/local/lib/python3.4/dist-packages/django/contrib/auth/decorators.py", line 22, in _wrapped_view
    return view_func(request, *args, **kwargs)
  File "/webapps/lis2/receivematerial/views.py", line 52, in tubes_get
    podrazledeniye = Podrazdeleniya.objects.get(pk=request.GET["from"])
  File "/usr/local/lib/python3.4/dist-packages/django/db/models/manager.py", line 127, in manager_method
    return getattr(self.get_queryset(), name)(*args, **kwargs)
  File "/usr/local/lib/python3.4/dist-packages/django/db/models/query.py", line 325, in get
    clone = self.filter(*args, **kwargs)
  File "/usr/local/lib/python3.4/dist-packages/django/db/models/query.py", line 679, in filter
    return self._filter_or_exclude(False, *args, **kwargs)
  File "/usr/local/lib/python3.4/dist-packages/django/db/models/query.py", line 697, in _filter_or_exclude
    clone.query.add_q(Q(*args, **kwargs))
  File "/usr/local/lib/python3.4/dist-packages/django/db/models/sql/query.py", line 1309, in add_q
    clause, require_inner = self._add_q(where_part, self.used_aliases)
  File "/usr/local/lib/python3.4/dist-packages/django/db/models/sql/query.py", line 1337, in _add_q
    allow_joins=allow_joins, split_subq=split_subq,
  File "/usr/local/lib/python3.4/dist-packages/django/db/models/sql/query.py", line 1208, in build_filter
    condition = self.build_lookup(lookups, col, value)
  File "/usr/local/lib/python3.4/dist-packages/django/db/models/sql/query.py", line 1101, in build_lookup
    return final_lookup(lhs, rhs)
  File "/usr/local/lib/python3.4/dist-packages/django/db/models/lookups.py", line 101, in __init__
    self.rhs = self.get_prep_lookup()
  File "/usr/local/lib/python3.4/dist-packages/django/db/models/lookups.py", line 139, in get_prep_lookup
    return self.lhs.output_field.get_prep_lookup(self.lookup_name, self.rhs)
  File "/usr/local/lib/python3.4/dist-packages/django/db/models/fields/__init__.py", line 727, in get_prep_lookup
    return self.get_prep_value(value)
  File "/usr/local/lib/python3.4/dist-packages/django/db/models/fields/__init__.py", line 985, in get_prep_value
    return int(value)
ValueError: invalid literal for int() with base 10: 'undefined'
Internal Server Error: /tubes/get
Traceback (most recent call last):
  File "/usr/local/lib/python3.4/dist-packages/django/core/handlers/base.py", line 132, in get_response
    response = wrapped_callback(request, *callback_args, **callback_kwargs)
  File "/usr/local/lib/python3.4/dist-packages/django/contrib/auth/decorators.py", line 22, in _wrapped_view
    return view_func(request, *args, **kwargs)
  File "/webapps/lis2/receivematerial/views.py", line 52, in tubes_get
    podrazledeniye = Podrazdeleniya.objects.get(pk=request.GET["from"])
  File "/usr/local/lib/python3.4/dist-packages/django/db/models/manager.py", line 127, in manager_method
    return getattr(self.get_queryset(), name)(*args, **kwargs)
  File "/usr/local/lib/python3.4/dist-packages/django/db/models/query.py", line 325, in get
    clone = self.filter(*args, **kwargs)
  File "/usr/local/lib/python3.4/dist-packages/django/db/models/query.py", line 679, in filter
    return self._filter_or_exclude(False, *args, **kwargs)
  File "/usr/local/lib/python3.4/dist-packages/django/db/models/query.py", line 697, in _filter_or_exclude
    clone.query.add_q(Q(*args, **kwargs))
  File "/usr/local/lib/python3.4/dist-packages/django/db/models/sql/query.py", line 1309, in add_q
    clause, require_inner = self._add_q(where_part, self.used_aliases)
  File "/usr/local/lib/python3.4/dist-packages/django/db/models/sql/query.py", line 1337, in _add_q
    allow_joins=allow_joins, split_subq=split_subq,
  File "/usr/local/lib/python3.4/dist-packages/django/db/models/sql/query.py", line 1208, in build_filter
    condition = self.build_lookup(lookups, col, value)
  File "/usr/local/lib/python3.4/dist-packages/django/db/models/sql/query.py", line 1101, in build_lookup
    return final_lookup(lhs, rhs)
  File "/usr/local/lib/python3.4/dist-packages/django/db/models/lookups.py", line 101, in __init__
    self.rhs = self.get_prep_lookup()
  File "/usr/local/lib/python3.4/dist-packages/django/db/models/lookups.py", line 139, in get_prep_lookup
    return self.lhs.output_field.get_prep_lookup(self.lookup_name, self.rhs)
  File "/usr/local/lib/python3.4/dist-packages/django/db/models/fields/__init__.py", line 727, in get_prep_lookup
    return self.get_prep_value(value)
  File "/usr/local/lib/python3.4/dist-packages/django/db/models/fields/__init__.py", line 985, in get_prep_value
    return int(value)
ValueError: invalid literal for int() with base 10: 'undefined'
Internal Server Error: /tubes/get
Traceback (most recent call last):
  File "/usr/local/lib/python3.4/dist-packages/django/core/handlers/base.py", line 132, in get_response
    response = wrapped_callback(request, *callback_args, **callback_kwargs)
  File "/usr/local/lib/python3.4/dist-packages/django/contrib/auth/decorators.py", line 22, in _wrapped_view
    return view_func(request, *args, **kwargs)
  File "/webapps/lis2/receivematerial/views.py", line 52, in tubes_get
    podrazledeniye = Podrazdeleniya.objects.get(pk=request.GET["from"])
  File "/usr/local/lib/python3.4/dist-packages/django/db/models/manager.py", line 127, in manager_method
    return getattr(self.get_queryset(), name)(*args, **kwargs)
  File "/usr/local/lib/python3.4/dist-packages/django/db/models/query.py", line 325, in get
    clone = self.filter(*args, **kwargs)
  File "/usr/local/lib/python3.4/dist-packages/django/db/models/query.py", line 679, in filter
    return self._filter_or_exclude(False, *args, **kwargs)
  File "/usr/local/lib/python3.4/dist-packages/django/db/models/query.py", line 697, in _filter_or_exclude
    clone.query.add_q(Q(*args, **kwargs))
  File "/usr/local/lib/python3.4/dist-packages/django/db/models/sql/query.py", line 1309, in add_q
    clause, require_inner = self._add_q(where_part, self.used_aliases)
  File "/usr/local/lib/python3.4/dist-packages/django/db/models/sql/query.py", line 1337, in _add_q
    allow_joins=allow_joins, split_subq=split_subq,
  File "/usr/local/lib/python3.4/dist-packages/django/db/models/sql/query.py", line 1208, in build_filter
    condition = self.build_lookup(lookups, col, value)
  File "/usr/local/lib/python3.4/dist-packages/django/db/models/sql/query.py", line 1101, in build_lookup
    return final_lookup(lhs, rhs)
  File "/usr/local/lib/python3.4/dist-packages/django/db/models/lookups.py", line 101, in __init__
    self.rhs = self.get_prep_lookup()
  File "/usr/local/lib/python3.4/dist-packages/django/db/models/lookups.py", line 139, in get_prep_lookup
    return self.lhs.output_field.get_prep_lookup(self.lookup_name, self.rhs)
  File "/usr/local/lib/python3.4/dist-packages/django/db/models/fields/__init__.py", line 727, in get_prep_lookup
    return self.get_prep_value(value)
  File "/usr/local/lib/python3.4/dist-packages/django/db/models/fields/__init__.py", line 985, in get_prep_value
    return int(value)
ValueError: invalid literal for int() with base 10: 'undefined'
Internal Server Error: /tubes/get
Traceback (most recent call last):
  File "/usr/local/lib/python3.4/dist-packages/django/core/handlers/base.py", line 132, in get_response
    response = wrapped_callback(request, *callback_args, **callback_kwargs)
  File "/usr/local/lib/python3.4/dist-packages/django/contrib/auth/decorators.py", line 22, in _wrapped_view
    return view_func(request, *args, **kwargs)
  File "/webapps/lis2/receivematerial/views.py", line 52, in tubes_get
    podrazledeniye = Podrazdeleniya.objects.get(pk=request.GET["from"])
  File "/usr/local/lib/python3.4/dist-packages/django/db/models/manager.py", line 127, in manager_method
    return getattr(self.get_queryset(), name)(*args, **kwargs)
  File "/usr/local/lib/python3.4/dist-packages/django/db/models/query.py", line 325, in get
    clone = self.filter(*args, **kwargs)
  File "/usr/local/lib/python3.4/dist-packages/django/db/models/query.py", line 679, in filter
    return self._filter_or_exclude(False, *args, **kwargs)
  File "/usr/local/lib/python3.4/dist-packages/django/db/models/query.py", line 697, in _filter_or_exclude
    clone.query.add_q(Q(*args, **kwargs))
  File "/usr/local/lib/python3.4/dist-packages/django/db/models/sql/query.py", line 1309, in add_q
    clause, require_inner = self._add_q(where_part, self.used_aliases)
  File "/usr/local/lib/python3.4/dist-packages/django/db/models/sql/query.py", line 1337, in _add_q
    allow_joins=allow_joins, split_subq=split_subq,
  File "/usr/local/lib/python3.4/dist-packages/django/db/models/sql/query.py", line 1208, in build_filter
    condition = self.build_lookup(lookups, col, value)
  File "/usr/local/lib/python3.4/dist-packages/django/db/models/sql/query.py", line 1101, in build_lookup
    return final_lookup(lhs, rhs)
  File "/usr/local/lib/python3.4/dist-packages/django/db/models/lookups.py", line 101, in __init__
    self.rhs = self.get_prep_lookup()
  File "/usr/local/lib/python3.4/dist-packages/django/db/models/lookups.py", line 139, in get_prep_lookup
    return self.lhs.output_field.get_prep_lookup(self.lookup_name, self.rhs)
  File "/usr/local/lib/python3.4/dist-packages/django/db/models/fields/__init__.py", line 727, in get_prep_lookup
    return self.get_prep_value(value)
  File "/usr/local/lib/python3.4/dist-packages/django/db/models/fields/__init__.py", line 985, in get_prep_value
    return int(value)
ValueError: invalid literal for int() with base 10: 'undefined'
Internal Server Error: /tubes/get
Traceback (most recent call last):
  File "/usr/local/lib/python3.4/dist-packages/django/core/handlers/base.py", line 132, in get_response
    response = wrapped_callback(request, *callback_args, **callback_kwargs)
  File "/usr/local/lib/python3.4/dist-packages/django/contrib/auth/decorators.py", line 22, in _wrapped_view
    return view_func(request, *args, **kwargs)
  File "/webapps/lis2/receivematerial/views.py", line 52, in tubes_get
    podrazledeniye = Podrazdeleniya.objects.get(pk=request.GET["from"])
  File "/usr/local/lib/python3.4/dist-packages/django/db/models/manager.py", line 127, in manager_method
    return getattr(self.get_queryset(), name)(*args, **kwargs)
  File "/usr/local/lib/python3.4/dist-packages/django/db/models/query.py", line 325, in get
    clone = self.filter(*args, **kwargs)
  File "/usr/local/lib/python3.4/dist-packages/django/db/models/query.py", line 679, in filter
    return self._filter_or_exclude(False, *args, **kwargs)
  File "/usr/local/lib/python3.4/dist-packages/django/db/models/query.py", line 697, in _filter_or_exclude
    clone.query.add_q(Q(*args, **kwargs))
  File "/usr/local/lib/python3.4/dist-packages/django/db/models/sql/query.py", line 1309, in add_q
    clause, require_inner = self._add_q(where_part, self.used_aliases)
  File "/usr/local/lib/python3.4/dist-packages/django/db/models/sql/query.py", line 1337, in _add_q
    allow_joins=allow_joins, split_subq=split_subq,
  File "/usr/local/lib/python3.4/dist-packages/django/db/models/sql/query.py", line 1208, in build_filter
    condition = self.build_lookup(lookups, col, value)
  File "/usr/local/lib/python3.4/dist-packages/django/db/models/sql/query.py", line 1101, in build_lookup
    return final_lookup(lhs, rhs)
  File "/usr/local/lib/python3.4/dist-packages/django/db/models/lookups.py", line 101, in __init__
    self.rhs = self.get_prep_lookup()
  File "/usr/local/lib/python3.4/dist-packages/django/db/models/lookups.py", line 139, in get_prep_lookup
    return self.lhs.output_field.get_prep_lookup(self.lookup_name, self.rhs)
  File "/usr/local/lib/python3.4/dist-packages/django/db/models/fields/__init__.py", line 727, in get_prep_lookup
    return self.get_prep_value(value)
  File "/usr/local/lib/python3.4/dist-packages/django/db/models/fields/__init__.py", line 985, in get_prep_value
    return int(value)
ValueError: invalid literal for int() with base 10: 'undefined'
Internal Server Error: /tubes/get
Traceback (most recent call last):
  File "/usr/local/lib/python3.4/dist-packages/django/core/handlers/base.py", line 132, in get_response
    response = wrapped_callback(request, *callback_args, **callback_kwargs)
  File "/usr/local/lib/python3.4/dist-packages/django/contrib/auth/decorators.py", line 22, in _wrapped_view
    return view_func(request, *args, **kwargs)
  File "/webapps/lis2/receivematerial/views.py", line 52, in tubes_get
    podrazledeniye = Podrazdeleniya.objects.get(pk=request.GET["from"])
  File "/usr/local/lib/python3.4/dist-packages/django/db/models/manager.py", line 127, in manager_method
    return getattr(self.get_queryset(), name)(*args, **kwargs)
  File "/usr/local/lib/python3.4/dist-packages/django/db/models/query.py", line 325, in get
    clone = self.filter(*args, **kwargs)
  File "/usr/local/lib/python3.4/dist-packages/django/db/models/query.py", line 679, in filter
    return self._filter_or_exclude(False, *args, **kwargs)
  File "/usr/local/lib/python3.4/dist-packages/django/db/models/query.py", line 697, in _filter_or_exclude
    clone.query.add_q(Q(*args, **kwargs))
  File "/usr/local/lib/python3.4/dist-packages/django/db/models/sql/query.py", line 1309, in add_q
    clause, require_inner = self._add_q(where_part, self.used_aliases)
  File "/usr/local/lib/python3.4/dist-packages/django/db/models/sql/query.py", line 1337, in _add_q
    allow_joins=allow_joins, split_subq=split_subq,
  File "/usr/local/lib/python3.4/dist-packages/django/db/models/sql/query.py", line 1208, in build_filter
    condition = self.build_lookup(lookups, col, value)
  File "/usr/local/lib/python3.4/dist-packages/django/db/models/sql/query.py", line 1101, in build_lookup
    return final_lookup(lhs, rhs)
  File "/usr/local/lib/python3.4/dist-packages/django/db/models/lookups.py", line 101, in __init__
    self.rhs = self.get_prep_lookup()
  File "/usr/local/lib/python3.4/dist-packages/django/db/models/lookups.py", line 139, in get_prep_lookup
    return self.lhs.output_field.get_prep_lookup(self.lookup_name, self.rhs)
  File "/usr/local/lib/python3.4/dist-packages/django/db/models/fields/__init__.py", line 727, in get_prep_lookup
    return self.get_prep_value(value)
  File "/usr/local/lib/python3.4/dist-packages/django/db/models/fields/__init__.py", line 985, in get_prep_value
    return int(value)
ValueError: invalid literal for int() with base 10: 'undefined'
Internal Server Error: /tubes/get
Traceback (most recent call last):
  File "/usr/local/lib/python3.4/dist-packages/django/core/handlers/base.py", line 132, in get_response
    response = wrapped_callback(request, *callback_args, **callback_kwargs)
  File "/usr/local/lib/python3.4/dist-packages/django/contrib/auth/decorators.py", line 22, in _wrapped_view
    return view_func(request, *args, **kwargs)
  File "/webapps/lis2/receivematerial/views.py", line 52, in tubes_get
    podrazledeniye = Podrazdeleniya.objects.get(pk=request.GET["from"])
  File "/usr/local/lib/python3.4/dist-packages/django/db/models/manager.py", line 127, in manager_method
    return getattr(self.get_queryset(), name)(*args, **kwargs)
  File "/usr/local/lib/python3.4/dist-packages/django/db/models/query.py", line 325, in get
    clone = self.filter(*args, **kwargs)
  File "/usr/local/lib/python3.4/dist-packages/django/db/models/query.py", line 679, in filter
    return self._filter_or_exclude(False, *args, **kwargs)
  File "/usr/local/lib/python3.4/dist-packages/django/db/models/query.py", line 697, in _filter_or_exclude
    clone.query.add_q(Q(*args, **kwargs))
  File "/usr/local/lib/python3.4/dist-packages/django/db/models/sql/query.py", line 1309, in add_q
    clause, require_inner = self._add_q(where_part, self.used_aliases)
  File "/usr/local/lib/python3.4/dist-packages/django/db/models/sql/query.py", line 1337, in _add_q
    allow_joins=allow_joins, split_subq=split_subq,
  File "/usr/local/lib/python3.4/dist-packages/django/db/models/sql/query.py", line 1208, in build_filter
    condition = self.build_lookup(lookups, col, value)
  File "/usr/local/lib/python3.4/dist-packages/django/db/models/sql/query.py", line 1101, in build_lookup
    return final_lookup(lhs, rhs)
  File "/usr/local/lib/python3.4/dist-packages/django/db/models/lookups.py", line 101, in __init__
    self.rhs = self.get_prep_lookup()
  File "/usr/local/lib/python3.4/dist-packages/django/db/models/lookups.py", line 139, in get_prep_lookup
    return self.lhs.output_field.get_prep_lookup(self.lookup_name, self.rhs)
  File "/usr/local/lib/python3.4/dist-packages/django/db/models/fields/__init__.py", line 727, in get_prep_lookup
    return self.get_prep_value(value)
  File "/usr/local/lib/python3.4/dist-packages/django/db/models/fields/__init__.py", line 985, in get_prep_value
    return int(value)
ValueError: invalid literal for int() with base 10: 'undefined'
Internal Server Error: /tubes/get
Traceback (most recent call last):
  File "/usr/local/lib/python3.4/dist-packages/django/core/handlers/base.py", line 132, in get_response
    response = wrapped_callback(request, *callback_args, **callback_kwargs)
  File "/usr/local/lib/python3.4/dist-packages/django/contrib/auth/decorators.py", line 22, in _wrapped_view
    return view_func(request, *args, **kwargs)
  File "/webapps/lis2/receivematerial/views.py", line 52, in tubes_get
    podrazledeniye = Podrazdeleniya.objects.get(pk=request.GET["from"])
  File "/usr/local/lib/python3.4/dist-packages/django/db/models/manager.py", line 127, in manager_method
    return getattr(self.get_queryset(), name)(*args, **kwargs)
  File "/usr/local/lib/python3.4/dist-packages/django/db/models/query.py", line 325, in get
    clone = self.filter(*args, **kwargs)
  File "/usr/local/lib/python3.4/dist-packages/django/db/models/query.py", line 679, in filter
    return self._filter_or_exclude(False, *args, **kwargs)
  File "/usr/local/lib/python3.4/dist-packages/django/db/models/query.py", line 697, in _filter_or_exclude
    clone.query.add_q(Q(*args, **kwargs))
  File "/usr/local/lib/python3.4/dist-packages/django/db/models/sql/query.py", line 1309, in add_q
    clause, require_inner = self._add_q(where_part, self.used_aliases)
  File "/usr/local/lib/python3.4/dist-packages/django/db/models/sql/query.py", line 1337, in _add_q
    allow_joins=allow_joins, split_subq=split_subq,
  File "/usr/local/lib/python3.4/dist-packages/django/db/models/sql/query.py", line 1208, in build_filter
    condition = self.build_lookup(lookups, col, value)
  File "/usr/local/lib/python3.4/dist-packages/django/db/models/sql/query.py", line 1101, in build_lookup
    return final_lookup(lhs, rhs)
  File "/usr/local/lib/python3.4/dist-packages/django/db/models/lookups.py", line 101, in __init__
    self.rhs = self.get_prep_lookup()
  File "/usr/local/lib/python3.4/dist-packages/django/db/models/lookups.py", line 139, in get_prep_lookup
    return self.lhs.output_field.get_prep_lookup(self.lookup_name, self.rhs)
  File "/usr/local/lib/python3.4/dist-packages/django/db/models/fields/__init__.py", line 727, in get_prep_lookup
    return self.get_prep_value(value)
  File "/usr/local/lib/python3.4/dist-packages/django/db/models/fields/__init__.py", line 985, in get_prep_value
    return int(value)
ValueError: invalid literal for int() with base 10: 'undefined'
Internal Server Error: /tubes/get
Traceback (most recent call last):
  File "/usr/local/lib/python3.4/dist-packages/django/core/handlers/base.py", line 132, in get_response
    response = wrapped_callback(request, *callback_args, **callback_kwargs)
  File "/usr/local/lib/python3.4/dist-packages/django/contrib/auth/decorators.py", line 22, in _wrapped_view
    return view_func(request, *args, **kwargs)
  File "/webapps/lis2/receivematerial/views.py", line 52, in tubes_get
    podrazledeniye = Podrazdeleniya.objects.get(pk=request.GET["from"])
  File "/usr/local/lib/python3.4/dist-packages/django/db/models/manager.py", line 127, in manager_method
    return getattr(self.get_queryset(), name)(*args, **kwargs)
  File "/usr/local/lib/python3.4/dist-packages/django/db/models/query.py", line 325, in get
    clone = self.filter(*args, **kwargs)
  File "/usr/local/lib/python3.4/dist-packages/django/db/models/query.py", line 679, in filter
    return self._filter_or_exclude(False, *args, **kwargs)
  File "/usr/local/lib/python3.4/dist-packages/django/db/models/query.py", line 697, in _filter_or_exclude
    clone.query.add_q(Q(*args, **kwargs))
  File "/usr/local/lib/python3.4/dist-packages/django/db/models/sql/query.py", line 1309, in add_q
    clause, require_inner = self._add_q(where_part, self.used_aliases)
  File "/usr/local/lib/python3.4/dist-packages/django/db/models/sql/query.py", line 1337, in _add_q
    allow_joins=allow_joins, split_subq=split_subq,
  File "/usr/local/lib/python3.4/dist-packages/django/db/models/sql/query.py", line 1208, in build_filter
    condition = self.build_lookup(lookups, col, value)
  File "/usr/local/lib/python3.4/dist-packages/django/db/models/sql/query.py", line 1101, in build_lookup
    return final_lookup(lhs, rhs)
  File "/usr/local/lib/python3.4/dist-packages/django/db/models/lookups.py", line 101, in __init__
    self.rhs = self.get_prep_lookup()
  File "/usr/local/lib/python3.4/dist-packages/django/db/models/lookups.py", line 139, in get_prep_lookup
    return self.lhs.output_field.get_prep_lookup(self.lookup_name, self.rhs)
  File "/usr/local/lib/python3.4/dist-packages/django/db/models/fields/__init__.py", line 727, in get_prep_lookup
    return self.get_prep_value(value)
  File "/usr/local/lib/python3.4/dist-packages/django/db/models/fields/__init__.py", line 985, in get_prep_value
    return int(value)
ValueError: invalid literal for int() with base 10: 'undefined'
Internal Server Error: /tubes/get
Traceback (most recent call last):
  File "/usr/local/lib/python3.4/dist-packages/django/core/handlers/base.py", line 132, in get_response
    response = wrapped_callback(request, *callback_args, **callback_kwargs)
  File "/usr/local/lib/python3.4/dist-packages/django/contrib/auth/decorators.py", line 22, in _wrapped_view
    return view_func(request, *args, **kwargs)
  File "/webapps/lis2/receivematerial/views.py", line 52, in tubes_get
    podrazledeniye = Podrazdeleniya.objects.get(pk=request.GET["from"])
  File "/usr/local/lib/python3.4/dist-packages/django/db/models/manager.py", line 127, in manager_method
    return getattr(self.get_queryset(), name)(*args, **kwargs)
  File "/usr/local/lib/python3.4/dist-packages/django/db/models/query.py", line 325, in get
    clone = self.filter(*args, **kwargs)
  File "/usr/local/lib/python3.4/dist-packages/django/db/models/query.py", line 679, in filter
    return self._filter_or_exclude(False, *args, **kwargs)
  File "/usr/local/lib/python3.4/dist-packages/django/db/models/query.py", line 697, in _filter_or_exclude
    clone.query.add_q(Q(*args, **kwargs))
  File "/usr/local/lib/python3.4/dist-packages/django/db/models/sql/query.py", line 1309, in add_q
    clause, require_inner = self._add_q(where_part, self.used_aliases)
  File "/usr/local/lib/python3.4/dist-packages/django/db/models/sql/query.py", line 1337, in _add_q
    allow_joins=allow_joins, split_subq=split_subq,
  File "/usr/local/lib/python3.4/dist-packages/django/db/models/sql/query.py", line 1208, in build_filter
    condition = self.build_lookup(lookups, col, value)
  File "/usr/local/lib/python3.4/dist-packages/django/db/models/sql/query.py", line 1101, in build_lookup
    return final_lookup(lhs, rhs)
  File "/usr/local/lib/python3.4/dist-packages/django/db/models/lookups.py", line 101, in __init__
    self.rhs = self.get_prep_lookup()
  File "/usr/local/lib/python3.4/dist-packages/django/db/models/lookups.py", line 139, in get_prep_lookup
    return self.lhs.output_field.get_prep_lookup(self.lookup_name, self.rhs)
  File "/usr/local/lib/python3.4/dist-packages/django/db/models/fields/__init__.py", line 727, in get_prep_lookup
    return self.get_prep_value(value)
  File "/usr/local/lib/python3.4/dist-packages/django/db/models/fields/__init__.py", line 985, in get_prep_value
    return int(value)
ValueError: invalid literal for int() with base 10: 'undefined'
Internal Server Error: /tubes/get
Traceback (most recent call last):
  File "/usr/local/lib/python3.4/dist-packages/django/core/handlers/base.py", line 132, in get_response
    response = wrapped_callback(request, *callback_args, **callback_kwargs)
  File "/usr/local/lib/python3.4/dist-packages/django/contrib/auth/decorators.py", line 22, in _wrapped_view
    return view_func(request, *args, **kwargs)
  File "/webapps/lis2/receivematerial/views.py", line 54, in tubes_get
    tubes = TubesRegistration.objects.filter(doc_get__podrazledeniye__pk=request.GET["from"])
  File "/usr/local/lib/python3.4/dist-packages/django/db/models/manager.py", line 127, in manager_method
    return getattr(self.get_queryset(), name)(*args, **kwargs)
  File "/usr/local/lib/python3.4/dist-packages/django/db/models/query.py", line 679, in filter
    return self._filter_or_exclude(False, *args, **kwargs)
  File "/usr/local/lib/python3.4/dist-packages/django/db/models/query.py", line 697, in _filter_or_exclude
    clone.query.add_q(Q(*args, **kwargs))
  File "/usr/local/lib/python3.4/dist-packages/django/db/models/sql/query.py", line 1309, in add_q
    clause, require_inner = self._add_q(where_part, self.used_aliases)
  File "/usr/local/lib/python3.4/dist-packages/django/db/models/sql/query.py", line 1337, in _add_q
    allow_joins=allow_joins, split_subq=split_subq,
  File "/usr/local/lib/python3.4/dist-packages/django/db/models/sql/query.py", line 1199, in build_filter
    lookups, value)
  File "/usr/local/lib/python3.4/dist-packages/django/db/models/fields/related.py", line 1725, in get_lookup_constraint
    raise exceptions.FieldError('Relation fields do not support nested lookups')
django.core.exceptions.FieldError: Relation fields do not support nested lookups
Internal Server Error: /tubes/get
Traceback (most recent call last):
  File "/usr/local/lib/python3.4/dist-packages/django/core/handlers/base.py", line 132, in get_response
    response = wrapped_callback(request, *callback_args, **callback_kwargs)
  File "/usr/local/lib/python3.4/dist-packages/django/contrib/auth/decorators.py", line 22, in _wrapped_view
    return view_func(request, *args, **kwargs)
  File "/webapps/lis2/receivematerial/views.py", line 54, in tubes_get
    tubes = TubesRegistration.objects.filter(doc_get__podrazledeniye__pk=request.GET["from"])
  File "/usr/local/lib/python3.4/dist-packages/django/db/models/manager.py", line 127, in manager_method
    return getattr(self.get_queryset(), name)(*args, **kwargs)
  File "/usr/local/lib/python3.4/dist-packages/django/db/models/query.py", line 679, in filter
    return self._filter_or_exclude(False, *args, **kwargs)
  File "/usr/local/lib/python3.4/dist-packages/django/db/models/query.py", line 697, in _filter_or_exclude
    clone.query.add_q(Q(*args, **kwargs))
  File "/usr/local/lib/python3.4/dist-packages/django/db/models/sql/query.py", line 1309, in add_q
    clause, require_inner = self._add_q(where_part, self.used_aliases)
  File "/usr/local/lib/python3.4/dist-packages/django/db/models/sql/query.py", line 1337, in _add_q
    allow_joins=allow_joins, split_subq=split_subq,
  File "/usr/local/lib/python3.4/dist-packages/django/db/models/sql/query.py", line 1199, in build_filter
    lookups, value)
  File "/usr/local/lib/python3.4/dist-packages/django/db/models/fields/related.py", line 1725, in get_lookup_constraint
    raise exceptions.FieldError('Relation fields do not support nested lookups')
django.core.exceptions.FieldError: Relation fields do not support nested lookups
Internal Server Error: /tubes/get
Traceback (most recent call last):
  File "/usr/local/lib/python3.4/dist-packages/django/core/handlers/base.py", line 132, in get_response
    response = wrapped_callback(request, *callback_args, **callback_kwargs)
  File "/usr/local/lib/python3.4/dist-packages/django/contrib/auth/decorators.py", line 22, in _wrapped_view
    return view_func(request, *args, **kwargs)
  File "/webapps/lis2/receivematerial/views.py", line 54, in tubes_get
    tubes = TubesRegistration.objects.filter(doc_get__podrazledeniye__pk=request.GET["from"])
  File "/usr/local/lib/python3.4/dist-packages/django/db/models/manager.py", line 127, in manager_method
    return getattr(self.get_queryset(), name)(*args, **kwargs)
  File "/usr/local/lib/python3.4/dist-packages/django/db/models/query.py", line 679, in filter
    return self._filter_or_exclude(False, *args, **kwargs)
  File "/usr/local/lib/python3.4/dist-packages/django/db/models/query.py", line 697, in _filter_or_exclude
    clone.query.add_q(Q(*args, **kwargs))
  File "/usr/local/lib/python3.4/dist-packages/django/db/models/sql/query.py", line 1309, in add_q
    clause, require_inner = self._add_q(where_part, self.used_aliases)
  File "/usr/local/lib/python3.4/dist-packages/django/db/models/sql/query.py", line 1337, in _add_q
    allow_joins=allow_joins, split_subq=split_subq,
  File "/usr/local/lib/python3.4/dist-packages/django/db/models/sql/query.py", line 1199, in build_filter
    lookups, value)
  File "/usr/local/lib/python3.4/dist-packages/django/db/models/fields/related.py", line 1725, in get_lookup_constraint
    raise exceptions.FieldError('Relation fields do not support nested lookups')
django.core.exceptions.FieldError: Relation fields do not support nested lookups
Internal Server Error: /tubes/get
Traceback (most recent call last):
  File "/usr/local/lib/python3.4/dist-packages/django/core/handlers/base.py", line 132, in get_response
    response = wrapped_callback(request, *callback_args, **callback_kwargs)
  File "/usr/local/lib/python3.4/dist-packages/django/contrib/auth/decorators.py", line 22, in _wrapped_view
    return view_func(request, *args, **kwargs)
  File "/webapps/lis2/receivematerial/views.py", line 54, in tubes_get
    tubes = TubesRegistration.objects.filter(doc_get__podrazledeniye__pk=request.GET["from"])
  File "/usr/local/lib/python3.4/dist-packages/django/db/models/manager.py", line 127, in manager_method
    return getattr(self.get_queryset(), name)(*args, **kwargs)
  File "/usr/local/lib/python3.4/dist-packages/django/db/models/query.py", line 679, in filter
    return self._filter_or_exclude(False, *args, **kwargs)
  File "/usr/local/lib/python3.4/dist-packages/django/db/models/query.py", line 697, in _filter_or_exclude
    clone.query.add_q(Q(*args, **kwargs))
  File "/usr/local/lib/python3.4/dist-packages/django/db/models/sql/query.py", line 1309, in add_q
    clause, require_inner = self._add_q(where_part, self.used_aliases)
  File "/usr/local/lib/python3.4/dist-packages/django/db/models/sql/query.py", line 1337, in _add_q
    allow_joins=allow_joins, split_subq=split_subq,
  File "/usr/local/lib/python3.4/dist-packages/django/db/models/sql/query.py", line 1199, in build_filter
    lookups, value)
  File "/usr/local/lib/python3.4/dist-packages/django/db/models/fields/related.py", line 1725, in get_lookup_constraint
    raise exceptions.FieldError('Relation fields do not support nested lookups')
django.core.exceptions.FieldError: Relation fields do not support nested lookups
Internal Server Error: /tubes/get
Traceback (most recent call last):
  File "/usr/local/lib/python3.4/dist-packages/django/core/handlers/base.py", line 132, in get_response
    response = wrapped_callback(request, *callback_args, **callback_kwargs)
  File "/usr/local/lib/python3.4/dist-packages/django/contrib/auth/decorators.py", line 22, in _wrapped_view
    return view_func(request, *args, **kwargs)
  File "/webapps/lis2/receivematerial/views.py", line 54, in tubes_get
    tubes = TubesRegistration.objects.filter(doc_get__podrazledeniye__pk=request.GET["from"])
  File "/usr/local/lib/python3.4/dist-packages/django/db/models/manager.py", line 127, in manager_method
    return getattr(self.get_queryset(), name)(*args, **kwargs)
  File "/usr/local/lib/python3.4/dist-packages/django/db/models/query.py", line 679, in filter
    return self._filter_or_exclude(False, *args, **kwargs)
  File "/usr/local/lib/python3.4/dist-packages/django/db/models/query.py", line 697, in _filter_or_exclude
    clone.query.add_q(Q(*args, **kwargs))
  File "/usr/local/lib/python3.4/dist-packages/django/db/models/sql/query.py", line 1309, in add_q
    clause, require_inner = self._add_q(where_part, self.used_aliases)
  File "/usr/local/lib/python3.4/dist-packages/django/db/models/sql/query.py", line 1337, in _add_q
    allow_joins=allow_joins, split_subq=split_subq,
  File "/usr/local/lib/python3.4/dist-packages/django/db/models/sql/query.py", line 1199, in build_filter
    lookups, value)
  File "/usr/local/lib/python3.4/dist-packages/django/db/models/fields/related.py", line 1725, in get_lookup_constraint
    raise exceptions.FieldError('Relation fields do not support nested lookups')
django.core.exceptions.FieldError: Relation fields do not support nested lookups
Internal Server Error: /tubes/get
Traceback (most recent call last):
  File "/usr/local/lib/python3.4/dist-packages/django/core/handlers/base.py", line 132, in get_response
    response = wrapped_callback(request, *callback_args, **callback_kwargs)
  File "/usr/local/lib/python3.4/dist-packages/django/contrib/auth/decorators.py", line 22, in _wrapped_view
    return view_func(request, *args, **kwargs)
  File "/webapps/lis2/receivematerial/views.py", line 54, in tubes_get
    tubes = TubesRegistration.objects.filter(doc_get__podrazledeniye__pk=request.GET["from"])
  File "/usr/local/lib/python3.4/dist-packages/django/db/models/manager.py", line 127, in manager_method
    return getattr(self.get_queryset(), name)(*args, **kwargs)
  File "/usr/local/lib/python3.4/dist-packages/django/db/models/query.py", line 679, in filter
    return self._filter_or_exclude(False, *args, **kwargs)
  File "/usr/local/lib/python3.4/dist-packages/django/db/models/query.py", line 697, in _filter_or_exclude
    clone.query.add_q(Q(*args, **kwargs))
  File "/usr/local/lib/python3.4/dist-packages/django/db/models/sql/query.py", line 1309, in add_q
    clause, require_inner = self._add_q(where_part, self.used_aliases)
  File "/usr/local/lib/python3.4/dist-packages/django/db/models/sql/query.py", line 1337, in _add_q
    allow_joins=allow_joins, split_subq=split_subq,
  File "/usr/local/lib/python3.4/dist-packages/django/db/models/sql/query.py", line 1199, in build_filter
    lookups, value)
  File "/usr/local/lib/python3.4/dist-packages/django/db/models/fields/related.py", line 1725, in get_lookup_constraint
    raise exceptions.FieldError('Relation fields do not support nested lookups')
django.core.exceptions.FieldError: Relation fields do not support nested lookups
Internal Server Error: /tubes/get
Traceback (most recent call last):
  File "/usr/local/lib/python3.4/dist-packages/django/core/handlers/base.py", line 132, in get_response
    response = wrapped_callback(request, *callback_args, **callback_kwargs)
  File "/usr/local/lib/python3.4/dist-packages/django/contrib/auth/decorators.py", line 22, in _wrapped_view
    return view_func(request, *args, **kwargs)
  File "/webapps/lis2/receivematerial/views.py", line 54, in tubes_get
    tubes = TubesRegistration.objects.filter(doc_get__podrazledeniye__pk=request.GET["from"])
  File "/usr/local/lib/python3.4/dist-packages/django/db/models/manager.py", line 127, in manager_method
    return getattr(self.get_queryset(), name)(*args, **kwargs)
  File "/usr/local/lib/python3.4/dist-packages/django/db/models/query.py", line 679, in filter
    return self._filter_or_exclude(False, *args, **kwargs)
  File "/usr/local/lib/python3.4/dist-packages/django/db/models/query.py", line 697, in _filter_or_exclude
    clone.query.add_q(Q(*args, **kwargs))
  File "/usr/local/lib/python3.4/dist-packages/django/db/models/sql/query.py", line 1309, in add_q
    clause, require_inner = self._add_q(where_part, self.used_aliases)
  File "/usr/local/lib/python3.4/dist-packages/django/db/models/sql/query.py", line 1337, in _add_q
    allow_joins=allow_joins, split_subq=split_subq,
  File "/usr/local/lib/python3.4/dist-packages/django/db/models/sql/query.py", line 1199, in build_filter
    lookups, value)
  File "/usr/local/lib/python3.4/dist-packages/django/db/models/fields/related.py", line 1725, in get_lookup_constraint
    raise exceptions.FieldError('Relation fields do not support nested lookups')
django.core.exceptions.FieldError: Relation fields do not support nested lookups
Internal Server Error: /tubes/get
Traceback (most recent call last):
  File "/usr/local/lib/python3.4/dist-packages/django/core/handlers/base.py", line 132, in get_response
    response = wrapped_callback(request, *callback_args, **callback_kwargs)
  File "/usr/local/lib/python3.4/dist-packages/django/contrib/auth/decorators.py", line 22, in _wrapped_view
    return view_func(request, *args, **kwargs)
  File "/webapps/lis2/receivematerial/views.py", line 54, in tubes_get
    tubes = TubesRegistration.objects.filter(doc_get__podrazledeniye__pk=request.GET["from"])
  File "/usr/local/lib/python3.4/dist-packages/django/db/models/manager.py", line 127, in manager_method
    return getattr(self.get_queryset(), name)(*args, **kwargs)
  File "/usr/local/lib/python3.4/dist-packages/django/db/models/query.py", line 679, in filter
    return self._filter_or_exclude(False, *args, **kwargs)
  File "/usr/local/lib/python3.4/dist-packages/django/db/models/query.py", line 697, in _filter_or_exclude
    clone.query.add_q(Q(*args, **kwargs))
  File "/usr/local/lib/python3.4/dist-packages/django/db/models/sql/query.py", line 1309, in add_q
    clause, require_inner = self._add_q(where_part, self.used_aliases)
  File "/usr/local/lib/python3.4/dist-packages/django/db/models/sql/query.py", line 1337, in _add_q
    allow_joins=allow_joins, split_subq=split_subq,
  File "/usr/local/lib/python3.4/dist-packages/django/db/models/sql/query.py", line 1199, in build_filter
    lookups, value)
  File "/usr/local/lib/python3.4/dist-packages/django/db/models/fields/related.py", line 1725, in get_lookup_constraint
    raise exceptions.FieldError('Relation fields do not support nested lookups')
django.core.exceptions.FieldError: Relation fields do not support nested lookups
Internal Server Error: /tubes/get
Traceback (most recent call last):
  File "/usr/local/lib/python3.4/dist-packages/django/core/handlers/base.py", line 132, in get_response
    response = wrapped_callback(request, *callback_args, **callback_kwargs)
  File "/usr/local/lib/python3.4/dist-packages/django/contrib/auth/decorators.py", line 22, in _wrapped_view
    return view_func(request, *args, **kwargs)
  File "/webapps/lis2/receivematerial/views.py", line 52, in tubes_get
    podrazledeniye = Podrazdeleniya.objects.get(pk=request.GET["from"])
  File "/usr/local/lib/python3.4/dist-packages/django/db/models/manager.py", line 127, in manager_method
    return getattr(self.get_queryset(), name)(*args, **kwargs)
  File "/usr/local/lib/python3.4/dist-packages/django/db/models/query.py", line 325, in get
    clone = self.filter(*args, **kwargs)
  File "/usr/local/lib/python3.4/dist-packages/django/db/models/query.py", line 679, in filter
    return self._filter_or_exclude(False, *args, **kwargs)
  File "/usr/local/lib/python3.4/dist-packages/django/db/models/query.py", line 697, in _filter_or_exclude
    clone.query.add_q(Q(*args, **kwargs))
  File "/usr/local/lib/python3.4/dist-packages/django/db/models/sql/query.py", line 1309, in add_q
    clause, require_inner = self._add_q(where_part, self.used_aliases)
  File "/usr/local/lib/python3.4/dist-packages/django/db/models/sql/query.py", line 1337, in _add_q
    allow_joins=allow_joins, split_subq=split_subq,
  File "/usr/local/lib/python3.4/dist-packages/django/db/models/sql/query.py", line 1208, in build_filter
    condition = self.build_lookup(lookups, col, value)
  File "/usr/local/lib/python3.4/dist-packages/django/db/models/sql/query.py", line 1101, in build_lookup
    return final_lookup(lhs, rhs)
  File "/usr/local/lib/python3.4/dist-packages/django/db/models/lookups.py", line 101, in __init__
    self.rhs = self.get_prep_lookup()
  File "/usr/local/lib/python3.4/dist-packages/django/db/models/lookups.py", line 139, in get_prep_lookup
    return self.lhs.output_field.get_prep_lookup(self.lookup_name, self.rhs)
  File "/usr/local/lib/python3.4/dist-packages/django/db/models/fields/__init__.py", line 727, in get_prep_lookup
    return self.get_prep_value(value)
  File "/usr/local/lib/python3.4/dist-packages/django/db/models/fields/__init__.py", line 985, in get_prep_value
    return int(value)
ValueError: invalid literal for int() with base 10: 'undefined'
Internal Server Error: /tubes/get
Traceback (most recent call last):
  File "/usr/local/lib/python3.4/dist-packages/django/core/handlers/base.py", line 132, in get_response
    response = wrapped_callback(request, *callback_args, **callback_kwargs)
  File "/usr/local/lib/python3.4/dist-packages/django/contrib/auth/decorators.py", line 22, in _wrapped_view
    return view_func(request, *args, **kwargs)
  File "/webapps/lis2/receivematerial/views.py", line 52, in tubes_get
    podrazledeniye = Podrazdeleniya.objects.get(pk=request.GET["from"])
  File "/usr/local/lib/python3.4/dist-packages/django/db/models/manager.py", line 127, in manager_method
    return getattr(self.get_queryset(), name)(*args, **kwargs)
  File "/usr/local/lib/python3.4/dist-packages/django/db/models/query.py", line 325, in get
    clone = self.filter(*args, **kwargs)
  File "/usr/local/lib/python3.4/dist-packages/django/db/models/query.py", line 679, in filter
    return self._filter_or_exclude(False, *args, **kwargs)
  File "/usr/local/lib/python3.4/dist-packages/django/db/models/query.py", line 697, in _filter_or_exclude
    clone.query.add_q(Q(*args, **kwargs))
  File "/usr/local/lib/python3.4/dist-packages/django/db/models/sql/query.py", line 1309, in add_q
    clause, require_inner = self._add_q(where_part, self.used_aliases)
  File "/usr/local/lib/python3.4/dist-packages/django/db/models/sql/query.py", line 1337, in _add_q
    allow_joins=allow_joins, split_subq=split_subq,
  File "/usr/local/lib/python3.4/dist-packages/django/db/models/sql/query.py", line 1208, in build_filter
    condition = self.build_lookup(lookups, col, value)
  File "/usr/local/lib/python3.4/dist-packages/django/db/models/sql/query.py", line 1101, in build_lookup
    return final_lookup(lhs, rhs)
  File "/usr/local/lib/python3.4/dist-packages/django/db/models/lookups.py", line 101, in __init__
    self.rhs = self.get_prep_lookup()
  File "/usr/local/lib/python3.4/dist-packages/django/db/models/lookups.py", line 139, in get_prep_lookup
    return self.lhs.output_field.get_prep_lookup(self.lookup_name, self.rhs)
  File "/usr/local/lib/python3.4/dist-packages/django/db/models/fields/__init__.py", line 727, in get_prep_lookup
    return self.get_prep_value(value)
  File "/usr/local/lib/python3.4/dist-packages/django/db/models/fields/__init__.py", line 985, in get_prep_value
    return int(value)
ValueError: invalid literal for int() with base 10: 'undefined'
Internal Server Error: /tubes/get
Traceback (most recent call last):
  File "/usr/local/lib/python3.4/dist-packages/django/db/models/options.py", line 552, in get_field
    return self.fields_map[field_name]
KeyError: 'issledovaniya_set'

During handling of the above exception, another exception occurred:

Traceback (most recent call last):
  File "/usr/local/lib/python3.4/dist-packages/django/db/models/sql/query.py", line 1367, in names_to_path
    field = opts.get_field(name)
  File "/usr/local/lib/python3.4/dist-packages/django/db/models/options.py", line 554, in get_field
    raise FieldDoesNotExist('%s has no field named %r' % (self.object_name, field_name))
django.core.exceptions.FieldDoesNotExist: TubesRegistration has no field named 'issledovaniya_set'

During handling of the above exception, another exception occurred:

Traceback (most recent call last):
  File "/usr/local/lib/python3.4/dist-packages/django/core/handlers/base.py", line 132, in get_response
    response = wrapped_callback(request, *callback_args, **callback_kwargs)
  File "/usr/local/lib/python3.4/dist-packages/django/contrib/auth/decorators.py", line 22, in _wrapped_view
    return view_func(request, *args, **kwargs)
  File "/webapps/lis2/receivematerial/views.py", line 54, in tubes_get
    for tube in TubesRegistration.objects.filter(doc_get=doc, notice="", doc_recive__isnull=True, issledovaniya_set__research__subgroup=subgroup_lab):
  File "/usr/local/lib/python3.4/dist-packages/django/db/models/manager.py", line 127, in manager_method
    return getattr(self.get_queryset(), name)(*args, **kwargs)
  File "/usr/local/lib/python3.4/dist-packages/django/db/models/query.py", line 679, in filter
    return self._filter_or_exclude(False, *args, **kwargs)
  File "/usr/local/lib/python3.4/dist-packages/django/db/models/query.py", line 697, in _filter_or_exclude
    clone.query.add_q(Q(*args, **kwargs))
  File "/usr/local/lib/python3.4/dist-packages/django/db/models/sql/query.py", line 1309, in add_q
    clause, require_inner = self._add_q(where_part, self.used_aliases)
  File "/usr/local/lib/python3.4/dist-packages/django/db/models/sql/query.py", line 1337, in _add_q
    allow_joins=allow_joins, split_subq=split_subq,
  File "/usr/local/lib/python3.4/dist-packages/django/db/models/sql/query.py", line 1149, in build_filter
    lookups, parts, reffed_expression = self.solve_lookup_type(arg)
  File "/usr/local/lib/python3.4/dist-packages/django/db/models/sql/query.py", line 1035, in solve_lookup_type
    _, field, _, lookup_parts = self.names_to_path(lookup_splitted, self.get_meta())
  File "/usr/local/lib/python3.4/dist-packages/django/db/models/sql/query.py", line 1396, in names_to_path
    "Choices are: %s" % (name, ", ".join(available)))
django.core.exceptions.FieldError: Cannot resolve keyword 'issledovaniya_set' into field. Choices are: barcode, doc_get, doc_get_id, doc_recive, doc_recive_id, id, issledovaniya, notice, time_get, time_recive, type, type_id
Internal Server Error: /tubes/get
Traceback (most recent call last):
  File "/usr/local/lib/python3.4/dist-packages/django/db/models/options.py", line 552, in get_field
    return self.fields_map[field_name]
KeyError: 'issledovaniya_set'

During handling of the above exception, another exception occurred:

Traceback (most recent call last):
  File "/usr/local/lib/python3.4/dist-packages/django/db/models/sql/query.py", line 1367, in names_to_path
    field = opts.get_field(name)
  File "/usr/local/lib/python3.4/dist-packages/django/db/models/options.py", line 554, in get_field
    raise FieldDoesNotExist('%s has no field named %r' % (self.object_name, field_name))
django.core.exceptions.FieldDoesNotExist: TubesRegistration has no field named 'issledovaniya_set'

During handling of the above exception, another exception occurred:

Traceback (most recent call last):
  File "/usr/local/lib/python3.4/dist-packages/django/core/handlers/base.py", line 132, in get_response
    response = wrapped_callback(request, *callback_args, **callback_kwargs)
  File "/usr/local/lib/python3.4/dist-packages/django/contrib/auth/decorators.py", line 22, in _wrapped_view
    return view_func(request, *args, **kwargs)
  File "/webapps/lis2/receivematerial/views.py", line 54, in tubes_get
    for tube in TubesRegistration.objects.filter(doc_get=doc, notice="", doc_recive__isnull=True, issledovaniya_set__research__subgroup=subgroup_lab):
  File "/usr/local/lib/python3.4/dist-packages/django/db/models/manager.py", line 127, in manager_method
    return getattr(self.get_queryset(), name)(*args, **kwargs)
  File "/usr/local/lib/python3.4/dist-packages/django/db/models/query.py", line 679, in filter
    return self._filter_or_exclude(False, *args, **kwargs)
  File "/usr/local/lib/python3.4/dist-packages/django/db/models/query.py", line 697, in _filter_or_exclude
    clone.query.add_q(Q(*args, **kwargs))
  File "/usr/local/lib/python3.4/dist-packages/django/db/models/sql/query.py", line 1309, in add_q
    clause, require_inner = self._add_q(where_part, self.used_aliases)
  File "/usr/local/lib/python3.4/dist-packages/django/db/models/sql/query.py", line 1337, in _add_q
    allow_joins=allow_joins, split_subq=split_subq,
  File "/usr/local/lib/python3.4/dist-packages/django/db/models/sql/query.py", line 1149, in build_filter
    lookups, parts, reffed_expression = self.solve_lookup_type(arg)
  File "/usr/local/lib/python3.4/dist-packages/django/db/models/sql/query.py", line 1035, in solve_lookup_type
    _, field, _, lookup_parts = self.names_to_path(lookup_splitted, self.get_meta())
  File "/usr/local/lib/python3.4/dist-packages/django/db/models/sql/query.py", line 1396, in names_to_path
    "Choices are: %s" % (name, ", ".join(available)))
django.core.exceptions.FieldError: Cannot resolve keyword 'issledovaniya_set' into field. Choices are: barcode, doc_get, doc_get_id, doc_recive, doc_recive_id, id, issledovaniya, notice, time_get, time_recive, type, type_id
Internal Server Error: /tubes/get
Traceback (most recent call last):
  File "/usr/local/lib/python3.4/dist-packages/django/db/models/options.py", line 552, in get_field
    return self.fields_map[field_name]
KeyError: 'issledovaniya_set'

During handling of the above exception, another exception occurred:

Traceback (most recent call last):
  File "/usr/local/lib/python3.4/dist-packages/django/db/models/sql/query.py", line 1367, in names_to_path
    field = opts.get_field(name)
  File "/usr/local/lib/python3.4/dist-packages/django/db/models/options.py", line 554, in get_field
    raise FieldDoesNotExist('%s has no field named %r' % (self.object_name, field_name))
django.core.exceptions.FieldDoesNotExist: TubesRegistration has no field named 'issledovaniya_set'

During handling of the above exception, another exception occurred:

Traceback (most recent call last):
  File "/usr/local/lib/python3.4/dist-packages/django/core/handlers/base.py", line 132, in get_response
    response = wrapped_callback(request, *callback_args, **callback_kwargs)
  File "/usr/local/lib/python3.4/dist-packages/django/contrib/auth/decorators.py", line 22, in _wrapped_view
    return view_func(request, *args, **kwargs)
  File "/webapps/lis2/receivematerial/views.py", line 54, in tubes_get
    for tube in TubesRegistration.objects.filter(doc_get=doc, notice="", doc_recive__isnull=True, issledovaniya_set__research__subgroup=subgroup_lab):
  File "/usr/local/lib/python3.4/dist-packages/django/db/models/manager.py", line 127, in manager_method
    return getattr(self.get_queryset(), name)(*args, **kwargs)
  File "/usr/local/lib/python3.4/dist-packages/django/db/models/query.py", line 679, in filter
    return self._filter_or_exclude(False, *args, **kwargs)
  File "/usr/local/lib/python3.4/dist-packages/django/db/models/query.py", line 697, in _filter_or_exclude
    clone.query.add_q(Q(*args, **kwargs))
  File "/usr/local/lib/python3.4/dist-packages/django/db/models/sql/query.py", line 1309, in add_q
    clause, require_inner = self._add_q(where_part, self.used_aliases)
  File "/usr/local/lib/python3.4/dist-packages/django/db/models/sql/query.py", line 1337, in _add_q
    allow_joins=allow_joins, split_subq=split_subq,
  File "/usr/local/lib/python3.4/dist-packages/django/db/models/sql/query.py", line 1149, in build_filter
    lookups, parts, reffed_expression = self.solve_lookup_type(arg)
  File "/usr/local/lib/python3.4/dist-packages/django/db/models/sql/query.py", line 1035, in solve_lookup_type
    _, field, _, lookup_parts = self.names_to_path(lookup_splitted, self.get_meta())
  File "/usr/local/lib/python3.4/dist-packages/django/db/models/sql/query.py", line 1396, in names_to_path
    "Choices are: %s" % (name, ", ".join(available)))
django.core.exceptions.FieldError: Cannot resolve keyword 'issledovaniya_set' into field. Choices are: barcode, doc_get, doc_get_id, doc_recive, doc_recive_id, id, issledovaniya, notice, time_get, time_recive, type, type_id
Internal Server Error: /tubes/get
Traceback (most recent call last):
  File "/usr/local/lib/python3.4/dist-packages/django/core/handlers/base.py", line 132, in get_response
    response = wrapped_callback(request, *callback_args, **callback_kwargs)
  File "/usr/local/lib/python3.4/dist-packages/django/contrib/auth/decorators.py", line 22, in _wrapped_view
    return view_func(request, *args, **kwargs)
  File "/webapps/lis2/receivematerial/views.py", line 55, in tubes_get
    for tube in TubesRegistration.objects.filter(doc_get=doc, notice="", doc_recive__isnull=True, issledovaniya__research__subgroup__pk=subgroup_lab):
  File "/usr/local/lib/python3.4/dist-packages/django/db/models/manager.py", line 127, in manager_method
    return getattr(self.get_queryset(), name)(*args, **kwargs)
  File "/usr/local/lib/python3.4/dist-packages/django/db/models/query.py", line 679, in filter
    return self._filter_or_exclude(False, *args, **kwargs)
  File "/usr/local/lib/python3.4/dist-packages/django/db/models/query.py", line 697, in _filter_or_exclude
    clone.query.add_q(Q(*args, **kwargs))
  File "/usr/local/lib/python3.4/dist-packages/django/db/models/sql/query.py", line 1309, in add_q
    clause, require_inner = self._add_q(where_part, self.used_aliases)
  File "/usr/local/lib/python3.4/dist-packages/django/db/models/sql/query.py", line 1337, in _add_q
    allow_joins=allow_joins, split_subq=split_subq,
  File "/usr/local/lib/python3.4/dist-packages/django/db/models/sql/query.py", line 1208, in build_filter
    condition = self.build_lookup(lookups, col, value)
  File "/usr/local/lib/python3.4/dist-packages/django/db/models/sql/query.py", line 1101, in build_lookup
    return final_lookup(lhs, rhs)
  File "/usr/local/lib/python3.4/dist-packages/django/db/models/lookups.py", line 101, in __init__
    self.rhs = self.get_prep_lookup()
  File "/usr/local/lib/python3.4/dist-packages/django/db/models/lookups.py", line 139, in get_prep_lookup
    return self.lhs.output_field.get_prep_lookup(self.lookup_name, self.rhs)
  File "/usr/local/lib/python3.4/dist-packages/django/db/models/fields/__init__.py", line 727, in get_prep_lookup
    return self.get_prep_value(value)
  File "/usr/local/lib/python3.4/dist-packages/django/db/models/fields/__init__.py", line 985, in get_prep_value
    return int(value)
TypeError: int() argument must be a string or a number, not 'Subgroups'
Internal Server Error: /tubes/get
Traceback (most recent call last):
  File "/usr/local/lib/python3.4/dist-packages/django/core/handlers/base.py", line 132, in get_response
    response = wrapped_callback(request, *callback_args, **callback_kwargs)
  File "/usr/local/lib/python3.4/dist-packages/django/contrib/auth/decorators.py", line 22, in _wrapped_view
    return view_func(request, *args, **kwargs)
  File "/webapps/lis2/receivematerial/views.py", line 55, in tubes_get
    for tube in TubesRegistration.objects.filter(doc_get=doc, notice="", doc_recive__isnull=True, issledovaniya__research__subgroup__pk=subgroup_lab):
  File "/usr/local/lib/python3.4/dist-packages/django/db/models/manager.py", line 127, in manager_method
    return getattr(self.get_queryset(), name)(*args, **kwargs)
  File "/usr/local/lib/python3.4/dist-packages/django/db/models/query.py", line 679, in filter
    return self._filter_or_exclude(False, *args, **kwargs)
  File "/usr/local/lib/python3.4/dist-packages/django/db/models/query.py", line 697, in _filter_or_exclude
    clone.query.add_q(Q(*args, **kwargs))
  File "/usr/local/lib/python3.4/dist-packages/django/db/models/sql/query.py", line 1309, in add_q
    clause, require_inner = self._add_q(where_part, self.used_aliases)
  File "/usr/local/lib/python3.4/dist-packages/django/db/models/sql/query.py", line 1337, in _add_q
    allow_joins=allow_joins, split_subq=split_subq,
  File "/usr/local/lib/python3.4/dist-packages/django/db/models/sql/query.py", line 1208, in build_filter
    condition = self.build_lookup(lookups, col, value)
  File "/usr/local/lib/python3.4/dist-packages/django/db/models/sql/query.py", line 1101, in build_lookup
    return final_lookup(lhs, rhs)
  File "/usr/local/lib/python3.4/dist-packages/django/db/models/lookups.py", line 101, in __init__
    self.rhs = self.get_prep_lookup()
  File "/usr/local/lib/python3.4/dist-packages/django/db/models/lookups.py", line 139, in get_prep_lookup
    return self.lhs.output_field.get_prep_lookup(self.lookup_name, self.rhs)
  File "/usr/local/lib/python3.4/dist-packages/django/db/models/fields/__init__.py", line 727, in get_prep_lookup
    return self.get_prep_value(value)
  File "/usr/local/lib/python3.4/dist-packages/django/db/models/fields/__init__.py", line 985, in get_prep_value
    return int(value)
TypeError: int() argument must be a string or a number, not 'Subgroups'
Not Found: /favicon.ico
Not Found: /favicon.ico
